2024-05-29 17:33:22,706 INFO    StreamThr :371377 [internal.py:wandb_internal():86] W&B internal server running at pid: 371377, started at: 2024-05-29 17:33:22.706238
2024-05-29 17:33:22,707 DEBUG   HandlerThread:371377 [handler.py:handle_request():146] handle_request: status
2024-05-29 17:33:22,713 INFO    WriterThread:371377 [datastore.py:open_for_write():87] open: /home/uosai/Desktop/on-policy/onpolicy/scripts/results/StarCraft2/3m/rmappo/Original_Mappo/wandb/run-20240529_173322-pp602m8s/run-pp602m8s.wandb
2024-05-29 17:33:22,714 DEBUG   SenderThread:371377 [sender.py:send():382] send: header
2024-05-29 17:33:22,736 DEBUG   SenderThread:371377 [sender.py:send():382] send: run
2024-05-29 17:33:23,301 INFO    SenderThread:371377 [dir_watcher.py:__init__():211] watching files in: /home/uosai/Desktop/on-policy/onpolicy/scripts/results/StarCraft2/3m/rmappo/Original_Mappo/wandb/run-20240529_173322-pp602m8s/files
2024-05-29 17:33:23,301 INFO    SenderThread:371377 [sender.py:_start_run_threads():1136] run started: pp602m8s with start time 1716971602.707121
2024-05-29 17:33:23,313 DEBUG   HandlerThread:371377 [handler.py:handle_request():146] handle_request: check_version
2024-05-29 17:33:23,313 DEBUG   SenderThread:371377 [sender.py:send_request():409] send_request: check_version
2024-05-29 17:33:23,369 DEBUG   HandlerThread:371377 [handler.py:handle_request():146] handle_request: run_start
2024-05-29 17:33:23,381 DEBUG   HandlerThread:371377 [system_info.py:__init__():27] System info init
2024-05-29 17:33:23,381 DEBUG   HandlerThread:371377 [system_info.py:__init__():42] System info init done
2024-05-29 17:33:23,381 INFO    HandlerThread:371377 [system_monitor.py:start():194] Starting system monitor
2024-05-29 17:33:23,381 INFO    SystemMonitor:371377 [system_monitor.py:_start():158] Starting system asset monitoring threads
2024-05-29 17:33:23,381 INFO    HandlerThread:371377 [system_monitor.py:probe():214] Collecting system info
2024-05-29 17:33:23,382 INFO    SystemMonitor:371377 [interfaces.py:start():190] Started cpu monitoring
2024-05-29 17:33:23,383 INFO    SystemMonitor:371377 [interfaces.py:start():190] Started disk monitoring
2024-05-29 17:33:23,383 INFO    SystemMonitor:371377 [interfaces.py:start():190] Started gpu monitoring
2024-05-29 17:33:23,384 INFO    SystemMonitor:371377 [interfaces.py:start():190] Started memory monitoring
2024-05-29 17:33:23,385 INFO    SystemMonitor:371377 [interfaces.py:start():190] Started network monitoring
2024-05-29 17:33:23,398 DEBUG   HandlerThread:371377 [system_info.py:probe():151] Probing system
2024-05-29 17:33:23,406 DEBUG   HandlerThread:371377 [system_info.py:_probe_git():136] Probing git
2024-05-29 17:33:23,420 DEBUG   HandlerThread:371377 [system_info.py:_probe_git():144] Probing git done
2024-05-29 17:33:23,421 DEBUG   HandlerThread:371377 [system_info.py:probe():199] Probing system done
2024-05-29 17:33:23,421 DEBUG   HandlerThread:371377 [system_monitor.py:probe():223] {'os': 'Linux-6.5.0-35-generic-x86_64-with-glibc2.35', 'python': '3.9.18', 'heartbeatAt': '2024-05-29T08:33:23.398823', 'startedAt': '2024-05-29T08:33:22.698896', 'docker': None, 'cuda': None, 'args': ('--seed', '293', '--env_name', 'StarCraft2', '--experiment_name', 'Original_Mappo', '--group_name', 'Original', '--use_reward_shaping', '--map_name', '3m', '--num_gpu', '1'), 'state': 'running', 'program': '/home/uosai/Desktop/on-policy/onpolicy/scripts/train/train_smac.py', 'codePathLocal': 'train_smac.py', 'codePath': 'onpolicy/scripts/train/train_smac.py', 'git': {'remote': 'https://github.com/singforai/on-policy.git', 'commit': '14d4b373e79555e79221655c211e9561875c023b'}, 'email': 'singfor7012@gmail.com', 'root': '/home/uosai/Desktop/on-policy', 'host': 'uos-desktop', 'username': 'uosai', 'executable': '/home/uosai/Desktop/miniconda3/envs/marl/bin/python', 'cpu_count': 12, 'cpu_count_logical': 24, 'cpu_freq': {'current': 4389.617958333333, 'min': 2200.0, 'max': 3700.0}, 'cpu_freq_per_core': [{'current': 4021.795, 'min': 2200.0, 'max': 3700.0}, {'current': 4400.833, 'min': 2200.0, 'max': 3700.0}, {'current': 4404.096, 'min': 2200.0, 'max': 3700.0}, {'current': 4414.489, 'min': 2200.0, 'max': 3700.0}, {'current': 4039.849, 'min': 2200.0, 'max': 3700.0}, {'current': 4405.562, 'min': 2200.0, 'max': 3700.0}, {'current': 4406.596, 'min': 2200.0, 'max': 3700.0}, {'current': 4352.07, 'min': 2200.0, 'max': 3700.0}, {'current': 4391.696, 'min': 2200.0, 'max': 3700.0}, {'current': 4390.549, 'min': 2200.0, 'max': 3700.0}, {'current': 3931.917, 'min': 2200.0, 'max': 3700.0}, {'current': 4406.218, 'min': 2200.0, 'max': 3700.0}, {'current': 4211.335, 'min': 2200.0, 'max': 3700.0}, {'current': 4404.09, 'min': 2200.0, 'max': 3700.0}, {'current': 4405.856, 'min': 2200.0, 'max': 3700.0}, {'current': 4404.097, 'min': 2200.0, 'max': 3700.0}, {'current': 4258.802, 'min': 2200.0, 'max': 3700.0}, {'current': 4395.738, 'min': 2200.0, 'max': 3700.0}, {'current': 4404.076, 'min': 2200.0, 'max': 3700.0}, {'current': 4387.005, 'min': 2200.0, 'max': 3700.0}, {'current': 4404.078, 'min': 2200.0, 'max': 3700.0}, {'current': 4403.599, 'min': 2200.0, 'max': 3700.0}, {'current': 3536.027, 'min': 2200.0, 'max': 3700.0}, {'current': 4404.084, 'min': 2200.0, 'max': 3700.0}], 'disk': {'/': {'total': 233.17998886108398, 'used': 189.81669235229492}}, 'gpu': 'NVIDIA GeForce RTX 3080', 'gpu_count': 2, 'gpu_devices': [{'name': 'NVIDIA GeForce RTX 3080', 'memory_total': 10737418240}, {'name': 'NVIDIA GeForce RTX 3080', 'memory_total': 10737418240}], 'memory': {'total': 62.709049224853516}}
2024-05-29 17:33:23,421 INFO    HandlerThread:371377 [system_monitor.py:probe():224] Finished collecting system info
2024-05-29 17:33:23,421 INFO    HandlerThread:371377 [system_monitor.py:probe():227] Publishing system info
2024-05-29 17:33:23,421 DEBUG   HandlerThread:371377 [system_info.py:_save_conda():208] Saving list of conda packages installed into the current environment
2024-05-29 17:33:24,304 INFO    Thread-12 :371377 [dir_watcher.py:_on_file_created():271] file/dir created: /home/uosai/Desktop/on-policy/onpolicy/scripts/results/StarCraft2/3m/rmappo/Original_Mappo/wandb/run-20240529_173322-pp602m8s/files/conda-environment.yaml
2024-05-29 17:33:26,251 DEBUG   HandlerThread:371377 [system_info.py:_save_conda():220] Saving conda packages done
2024-05-29 17:33:26,252 INFO    HandlerThread:371377 [system_monitor.py:probe():229] Finished publishing system info
2024-05-29 17:33:26,255 DEBUG   SenderThread:371377 [sender.py:send():382] send: files
2024-05-29 17:33:26,255 INFO    SenderThread:371377 [sender.py:_save_file():1403] saving file wandb-metadata.json with policy now
2024-05-29 17:33:26,260 DEBUG   HandlerThread:371377 [handler.py:handle_request():146] handle_request: python_packages
2024-05-29 17:33:26,261 DEBUG   SenderThread:371377 [sender.py:send_request():409] send_request: python_packages
2024-05-29 17:33:26,262 DEBUG   HandlerThread:371377 [handler.py:handle_request():146] handle_request: stop_status
2024-05-29 17:33:26,262 DEBUG   SenderThread:371377 [sender.py:send_request():409] send_request: stop_status
2024-05-29 17:33:26,263 DEBUG   HandlerThread:371377 [handler.py:handle_request():146] handle_request: internal_messages
2024-05-29 17:33:26,303 INFO    Thread-12 :371377 [dir_watcher.py:_on_file_modified():288] file/dir modified: /home/uosai/Desktop/on-policy/onpolicy/scripts/results/StarCraft2/3m/rmappo/Original_Mappo/wandb/run-20240529_173322-pp602m8s/files/conda-environment.yaml
2024-05-29 17:33:26,303 INFO    Thread-12 :371377 [dir_watcher.py:_on_file_created():271] file/dir created: /home/uosai/Desktop/on-policy/onpolicy/scripts/results/StarCraft2/3m/rmappo/Original_Mappo/wandb/run-20240529_173322-pp602m8s/files/requirements.txt
2024-05-29 17:33:26,303 INFO    Thread-12 :371377 [dir_watcher.py:_on_file_created():271] file/dir created: /home/uosai/Desktop/on-policy/onpolicy/scripts/results/StarCraft2/3m/rmappo/Original_Mappo/wandb/run-20240529_173322-pp602m8s/files/wandb-metadata.json
2024-05-29 17:33:26,501 DEBUG   SenderThread:371377 [sender.py:send():382] send: telemetry
2024-05-29 17:33:27,013 DEBUG   SenderThread:371377 [sender.py:send():382] send: telemetry
2024-05-29 17:33:27,076 INFO    wandb-upload_0:371377 [upload_job.py:push():131] Uploaded file /tmp/tmp2zlcmp7uwandb/uxovmjsy-wandb-metadata.json
2024-05-29 17:33:27,278 DEBUG   SenderThread:371377 [sender.py:send():382] send: telemetry
2024-05-29 17:33:28,278 DEBUG   HandlerThread:371377 [handler.py:handle_request():146] handle_request: status_report
2024-05-29 17:33:33,279 DEBUG   HandlerThread:371377 [handler.py:handle_request():146] handle_request: status_report
2024-05-29 17:33:35,306 INFO    Thread-12 :371377 [dir_watcher.py:_on_file_created():271] file/dir created: /home/uosai/Desktop/on-policy/onpolicy/scripts/results/StarCraft2/3m/rmappo/Original_Mappo/wandb/run-20240529_173322-pp602m8s/files/output.log
2024-05-29 17:33:36,936 DEBUG   HandlerThread:371377 [handler.py:handle_request():146] handle_request: partial_history
2024-05-29 17:33:36,936 DEBUG   HandlerThread:371377 [handler.py:handle_request():146] handle_request: partial_history
2024-05-29 17:33:36,936 DEBUG   HandlerThread:371377 [handler.py:handle_request():146] handle_request: partial_history
2024-05-29 17:33:36,937 DEBUG   HandlerThread:371377 [handler.py:handle_request():146] handle_request: partial_history
2024-05-29 17:33:37,306 INFO    Thread-12 :371377 [dir_watcher.py:_on_file_modified():288] file/dir modified: /home/uosai/Desktop/on-policy/onpolicy/scripts/results/StarCraft2/3m/rmappo/Original_Mappo/wandb/run-20240529_173322-pp602m8s/files/output.log
2024-05-29 17:33:37,307 INFO    Thread-12 :371377 [dir_watcher.py:_on_file_created():271] file/dir created: /home/uosai/Desktop/on-policy/onpolicy/scripts/results/StarCraft2/3m/rmappo/Original_Mappo/wandb/run-20240529_173322-pp602m8s/files/critic.pt
2024-05-29 17:33:37,307 INFO    Thread-12 :371377 [dir_watcher.py:_on_file_created():271] file/dir created: /home/uosai/Desktop/on-policy/onpolicy/scripts/results/StarCraft2/3m/rmappo/Original_Mappo/wandb/run-20240529_173322-pp602m8s/files/actor.pt
2024-05-29 17:33:37,331 DEBUG   HandlerThread:371377 [handler.py:handle_request():146] handle_request: partial_history
2024-05-29 17:33:37,332 DEBUG   HandlerThread:371377 [handler.py:handle_request():146] handle_request: partial_history
2024-05-29 17:33:37,332 DEBUG   HandlerThread:371377 [handler.py:handle_request():146] handle_request: partial_history
2024-05-29 17:33:37,332 DEBUG   HandlerThread:371377 [handler.py:handle_request():146] handle_request: partial_history
2024-05-29 17:33:37,333 DEBUG   HandlerThread:371377 [handler.py:handle_request():146] handle_request: partial_history
2024-05-29 17:33:38,332 DEBUG   HandlerThread:371377 [handler.py:handle_request():146] handle_request: status_report
2024-05-29 17:33:39,307 INFO    Thread-12 :371377 [dir_watcher.py:_on_file_modified():288] file/dir modified: /home/uosai/Desktop/on-policy/onpolicy/scripts/results/StarCraft2/3m/rmappo/Original_Mappo/wandb/run-20240529_173322-pp602m8s/files/output.log
2024-05-29 17:33:41,262 DEBUG   HandlerThread:371377 [handler.py:handle_request():146] handle_request: stop_status
2024-05-29 17:33:41,263 DEBUG   SenderThread:371377 [sender.py:send_request():409] send_request: stop_status
2024-05-29 17:33:41,265 DEBUG   HandlerThread:371377 [handler.py:handle_request():146] handle_request: internal_messages
2024-05-29 17:33:43,608 DEBUG   HandlerThread:371377 [handler.py:handle_request():146] handle_request: partial_history
2024-05-29 17:33:43,609 DEBUG   HandlerThread:371377 [handler.py:handle_request():146] handle_request: status_report
2024-05-29 17:33:43,610 DEBUG   HandlerThread:371377 [handler.py:handle_request():146] handle_request: partial_history
2024-05-29 17:33:45,309 INFO    Thread-12 :371377 [dir_watcher.py:_on_file_modified():288] file/dir modified: /home/uosai/Desktop/on-policy/onpolicy/scripts/results/StarCraft2/3m/rmappo/Original_Mappo/wandb/run-20240529_173322-pp602m8s/files/output.log
2024-05-29 17:33:48,610 DEBUG   HandlerThread:371377 [handler.py:handle_request():146] handle_request: status_report
2024-05-29 17:33:53,616 DEBUG   HandlerThread:371377 [handler.py:handle_request():146] handle_request: status_report
2024-05-29 17:33:54,312 INFO    Thread-12 :371377 [dir_watcher.py:_on_file_modified():288] file/dir modified: /home/uosai/Desktop/on-policy/onpolicy/scripts/results/StarCraft2/3m/rmappo/Original_Mappo/wandb/run-20240529_173322-pp602m8s/files/config.yaml
2024-05-29 17:33:56,262 DEBUG   HandlerThread:371377 [handler.py:handle_request():146] handle_request: stop_status
2024-05-29 17:33:56,262 DEBUG   SenderThread:371377 [sender.py:send_request():409] send_request: stop_status
2024-05-29 17:33:56,264 DEBUG   HandlerThread:371377 [handler.py:handle_request():146] handle_request: internal_messages
2024-05-29 17:33:59,475 DEBUG   HandlerThread:371377 [handler.py:handle_request():146] handle_request: status_report
2024-05-29 17:34:03,403 INFO    memory    :371377 [interfaces.py:monitor():140] Process proc.memory.rssMB has exited.
2024-05-29 17:34:03,403 DEBUG   SystemMonitor:371377 [system_monitor.py:_start():172] Starting system metrics aggregation loop
2024-05-29 17:34:03,403 DEBUG   SystemMonitor:371377 [system_monitor.py:_start():179] Finished system metrics aggregation loop
2024-05-29 17:34:03,404 DEBUG   SystemMonitor:371377 [system_monitor.py:_start():183] Publishing last batch of metrics
2024-05-29 17:34:03,405 DEBUG   SenderThread:371377 [sender.py:send():382] send: stats
2024-05-29 17:34:03,595 ERROR   FileStreamThread:371377 [file_stream.py:_handle_response():504] dropped chunk 404 Client Error: Not Found for url: https://api.wandb.ai/files/singfor7012/StarCraft2_3m/pp602m8s/file_stream
NoneType: None
2024-05-29 17:34:03,747 WARNING StreamThr :371377 [internal.py:is_dead():414] Internal process exiting, parent pid 370836 disappeared
2024-05-29 17:34:03,748 ERROR   StreamThr :371377 [internal.py:wandb_internal():152] Internal process shutdown.
2024-05-29 17:34:04,405 INFO    HandlerThread:371377 [handler.py:finish():869] shutting down handler
2024-05-29 17:34:04,405 INFO    HandlerThread:371377 [system_monitor.py:finish():203] Stopping system monitor
2024-05-29 17:34:04,405 INFO    HandlerThread:371377 [interfaces.py:finish():202] Joined cpu monitor
2024-05-29 17:34:04,405 INFO    HandlerThread:371377 [interfaces.py:finish():202] Joined disk monitor
2024-05-29 17:34:04,405 INFO    HandlerThread:371377 [interfaces.py:finish():202] Joined gpu monitor
2024-05-29 17:34:04,405 INFO    HandlerThread:371377 [interfaces.py:finish():202] Joined memory monitor
2024-05-29 17:34:04,405 INFO    HandlerThread:371377 [interfaces.py:finish():202] Joined network monitor
2024-05-29 17:34:04,405 INFO    WriterThread:371377 [datastore.py:close():296] close: /home/uosai/Desktop/on-policy/onpolicy/scripts/results/StarCraft2/3m/rmappo/Original_Mappo/wandb/run-20240529_173322-pp602m8s/run-pp602m8s.wandb
2024-05-29 17:34:04,406 INFO    SenderThread:371377 [sender.py:finish():1572] shutting down sender
2024-05-29 17:34:04,963 INFO    SenderThread:371377 [dir_watcher.py:finish():358] shutting down directory watcher
2024-05-29 17:34:05,314 INFO    SenderThread:371377 [dir_watcher.py:_on_file_modified():288] file/dir modified: /home/uosai/Desktop/on-policy/onpolicy/scripts/results/StarCraft2/3m/rmappo/Original_Mappo/wandb/run-20240529_173322-pp602m8s/files/output.log
2024-05-29 17:34:05,314 INFO    SenderThread:371377 [dir_watcher.py:finish():388] scan: /home/uosai/Desktop/on-policy/onpolicy/scripts/results/StarCraft2/3m/rmappo/Original_Mappo/wandb/run-20240529_173322-pp602m8s/files
2024-05-29 17:34:05,314 INFO    SenderThread:371377 [dir_watcher.py:finish():402] scan save: /home/uosai/Desktop/on-policy/onpolicy/scripts/results/StarCraft2/3m/rmappo/Original_Mappo/wandb/run-20240529_173322-pp602m8s/files/actor.pt actor.pt
2024-05-29 17:34:05,314 INFO    SenderThread:371377 [dir_watcher.py:finish():402] scan save: /home/uosai/Desktop/on-policy/onpolicy/scripts/results/StarCraft2/3m/rmappo/Original_Mappo/wandb/run-20240529_173322-pp602m8s/files/conda-environment.yaml conda-environment.yaml
2024-05-29 17:34:05,314 INFO    SenderThread:371377 [dir_watcher.py:finish():402] scan save: /home/uosai/Desktop/on-policy/onpolicy/scripts/results/StarCraft2/3m/rmappo/Original_Mappo/wandb/run-20240529_173322-pp602m8s/files/requirements.txt requirements.txt
2024-05-29 17:34:05,318 INFO    SenderThread:371377 [dir_watcher.py:finish():402] scan save: /home/uosai/Desktop/on-policy/onpolicy/scripts/results/StarCraft2/3m/rmappo/Original_Mappo/wandb/run-20240529_173322-pp602m8s/files/critic.pt critic.pt
2024-05-29 17:34:05,318 INFO    SenderThread:371377 [dir_watcher.py:finish():402] scan save: /home/uosai/Desktop/on-policy/onpolicy/scripts/results/StarCraft2/3m/rmappo/Original_Mappo/wandb/run-20240529_173322-pp602m8s/files/config.yaml config.yaml
2024-05-29 17:34:05,318 INFO    SenderThread:371377 [dir_watcher.py:finish():402] scan save: /home/uosai/Desktop/on-policy/onpolicy/scripts/results/StarCraft2/3m/rmappo/Original_Mappo/wandb/run-20240529_173322-pp602m8s/files/wandb-metadata.json wandb-metadata.json
2024-05-29 17:34:05,320 INFO    SenderThread:371377 [dir_watcher.py:finish():402] scan save: /home/uosai/Desktop/on-policy/onpolicy/scripts/results/StarCraft2/3m/rmappo/Original_Mappo/wandb/run-20240529_173322-pp602m8s/files/output.log output.log
2024-05-29 17:34:05,322 INFO    SenderThread:371377 [file_pusher.py:finish():175] shutting down file pusher
2024-05-29 17:34:05,322 INFO    SenderThread:371377 [file_pusher.py:join():181] waiting for file pusher
2024-05-29 17:34:05,506 ERROR   wandb-upload_0:371377 [internal_api.py:execute():373] 404 response executing GraphQL.
2024-05-29 17:34:05,506 ERROR   wandb-upload_0:371377 [internal_api.py:execute():374] {"errors":[{"message":"run StarCraft2_3m/pp602m8s not found during createRunFiles","path":["createRunFiles"]}],"data":{"createRunFiles":null}}
2024-05-29 17:34:05,507 ERROR   Thread-11 :371377 [step_upload.py:_handle_event():200] Failed to upload file: /home/uosai/Desktop/on-policy/onpolicy/scripts/results/StarCraft2/3m/rmappo/Original_Mappo/wandb/run-20240529_173322-pp602m8s/files/actor.pt
Traceback (most recent call last):
  File "/home/uosai/Desktop/miniconda3/envs/marl/lib/python3.9/site-packages/wandb/sdk/lib/retry.py", line 131, in __call__
    result = self._call_fn(*args, **kwargs)
  File "/home/uosai/Desktop/miniconda3/envs/marl/lib/python3.9/site-packages/wandb/sdk/internal/internal_api.py", line 369, in execute
    return self.client.execute(*args, **kwargs)  # type: ignore
  File "/home/uosai/Desktop/miniconda3/envs/marl/lib/python3.9/site-packages/wandb/vendor/gql-0.2.0/wandb_gql/client.py", line 52, in execute
    result = self._get_result(document, *args, **kwargs)
  File "/home/uosai/Desktop/miniconda3/envs/marl/lib/python3.9/site-packages/wandb/vendor/gql-0.2.0/wandb_gql/client.py", line 60, in _get_result
    return self.transport.execute(document, *args, **kwargs)
  File "/home/uosai/Desktop/miniconda3/envs/marl/lib/python3.9/site-packages/wandb/sdk/lib/gql_request.py", line 59, in execute
    request.raise_for_status()
  File "/home/uosai/Desktop/miniconda3/envs/marl/lib/python3.9/site-packages/requests/models.py", line 1021, in raise_for_status
    raise HTTPError(http_error_msg, response=self)
requests.exceptions.HTTPError: 404 Client Error: Not Found for url: https://api.wandb.ai/graphql

During handling of the above exception, another exception occurred:

Traceback (most recent call last):
  File "/home/uosai/Desktop/miniconda3/envs/marl/lib/python3.9/concurrent/futures/thread.py", line 58, in run
    result = self.fn(*self.args, **self.kwargs)
  File "/home/uosai/Desktop/miniconda3/envs/marl/lib/python3.9/site-packages/wandb/filesync/step_upload.py", line 288, in run_and_notify
    self._do_upload_sync(event)
  File "/home/uosai/Desktop/miniconda3/envs/marl/lib/python3.9/site-packages/wandb/filesync/step_upload.py", line 330, in _do_upload_sync
    job.run()
  File "/home/uosai/Desktop/miniconda3/envs/marl/lib/python3.9/site-packages/wandb/filesync/upload_job.py", line 57, in run
    self.push()
  File "/home/uosai/Desktop/miniconda3/envs/marl/lib/python3.9/site-packages/wandb/filesync/upload_job.py", line 106, in push
    _, upload_headers, result = self._api.upload_urls(project, [self.save_name])
  File "/home/uosai/Desktop/miniconda3/envs/marl/lib/python3.9/site-packages/wandb/apis/normalize.py", line 73, in wrapper
    raise err
  File "/home/uosai/Desktop/miniconda3/envs/marl/lib/python3.9/site-packages/wandb/apis/normalize.py", line 41, in wrapper
    return func(*args, **kwargs)
  File "/home/uosai/Desktop/miniconda3/envs/marl/lib/python3.9/site-packages/wandb/sdk/internal/internal_api.py", line 2384, in upload_urls
    query_result = self.gql(
  File "/home/uosai/Desktop/miniconda3/envs/marl/lib/python3.9/site-packages/wandb/sdk/internal/internal_api.py", line 341, in gql
    ret = self._retry_gql(
  File "/home/uosai/Desktop/miniconda3/envs/marl/lib/python3.9/site-packages/wandb/sdk/lib/retry.py", line 147, in __call__
    retry_timedelta_triggered = check_retry_fn(e)
  File "/home/uosai/Desktop/miniconda3/envs/marl/lib/python3.9/site-packages/wandb/util.py", line 907, in no_retry_auth
    raise CommError(
wandb.errors.CommError: It appears that you do not have permission to access the requested resource. Please reach out to the project owner to grant you access. If you have the correct permissions, verify that there are no issues with your networking setup.(Error 404: Not Found)
2024-05-29 17:34:05,511 ERROR   wandb-upload_1:371377 [internal_api.py:execute():373] 404 response executing GraphQL.
2024-05-29 17:34:05,511 ERROR   wandb-upload_1:371377 [internal_api.py:execute():374] {"errors":[{"message":"run StarCraft2_3m/pp602m8s not found during createRunFiles","path":["createRunFiles"]}],"data":{"createRunFiles":null}}
2024-05-29 17:34:05,511 ERROR   Thread-11 :371377 [step_upload.py:_handle_event():200] Failed to upload file: /home/uosai/Desktop/on-policy/onpolicy/scripts/results/StarCraft2/3m/rmappo/Original_Mappo/wandb/run-20240529_173322-pp602m8s/files/conda-environment.yaml
Traceback (most recent call last):
  File "/home/uosai/Desktop/miniconda3/envs/marl/lib/python3.9/site-packages/wandb/sdk/lib/retry.py", line 131, in __call__
    result = self._call_fn(*args, **kwargs)
  File "/home/uosai/Desktop/miniconda3/envs/marl/lib/python3.9/site-packages/wandb/sdk/internal/internal_api.py", line 369, in execute
    return self.client.execute(*args, **kwargs)  # type: ignore
  File "/home/uosai/Desktop/miniconda3/envs/marl/lib/python3.9/site-packages/wandb/vendor/gql-0.2.0/wandb_gql/client.py", line 52, in execute
    result = self._get_result(document, *args, **kwargs)
  File "/home/uosai/Desktop/miniconda3/envs/marl/lib/python3.9/site-packages/wandb/vendor/gql-0.2.0/wandb_gql/client.py", line 60, in _get_result
    return self.transport.execute(document, *args, **kwargs)
  File "/home/uosai/Desktop/miniconda3/envs/marl/lib/python3.9/site-packages/wandb/sdk/lib/gql_request.py", line 59, in execute
    request.raise_for_status()
  File "/home/uosai/Desktop/miniconda3/envs/marl/lib/python3.9/site-packages/requests/models.py", line 1021, in raise_for_status
    raise HTTPError(http_error_msg, response=self)
requests.exceptions.HTTPError: 404 Client Error: Not Found for url: https://api.wandb.ai/graphql

During handling of the above exception, another exception occurred:

Traceback (most recent call last):
  File "/home/uosai/Desktop/miniconda3/envs/marl/lib/python3.9/concurrent/futures/thread.py", line 58, in run
    result = self.fn(*self.args, **self.kwargs)
  File "/home/uosai/Desktop/miniconda3/envs/marl/lib/python3.9/site-packages/wandb/filesync/step_upload.py", line 288, in run_and_notify
    self._do_upload_sync(event)
  File "/home/uosai/Desktop/miniconda3/envs/marl/lib/python3.9/site-packages/wandb/filesync/step_upload.py", line 330, in _do_upload_sync
    job.run()
  File "/home/uosai/Desktop/miniconda3/envs/marl/lib/python3.9/site-packages/wandb/filesync/upload_job.py", line 57, in run
    self.push()
  File "/home/uosai/Desktop/miniconda3/envs/marl/lib/python3.9/site-packages/wandb/filesync/upload_job.py", line 106, in push
    _, upload_headers, result = self._api.upload_urls(project, [self.save_name])
  File "/home/uosai/Desktop/miniconda3/envs/marl/lib/python3.9/site-packages/wandb/apis/normalize.py", line 73, in wrapper
    raise err
  File "/home/uosai/Desktop/miniconda3/envs/marl/lib/python3.9/site-packages/wandb/apis/normalize.py", line 41, in wrapper
    return func(*args, **kwargs)
  File "/home/uosai/Desktop/miniconda3/envs/marl/lib/python3.9/site-packages/wandb/sdk/internal/internal_api.py", line 2384, in upload_urls
    query_result = self.gql(
  File "/home/uosai/Desktop/miniconda3/envs/marl/lib/python3.9/site-packages/wandb/sdk/internal/internal_api.py", line 341, in gql
    ret = self._retry_gql(
  File "/home/uosai/Desktop/miniconda3/envs/marl/lib/python3.9/site-packages/wandb/sdk/lib/retry.py", line 147, in __call__
    retry_timedelta_triggered = check_retry_fn(e)
  File "/home/uosai/Desktop/miniconda3/envs/marl/lib/python3.9/site-packages/wandb/util.py", line 907, in no_retry_auth
    raise CommError(
wandb.errors.CommError: It appears that you do not have permission to access the requested resource. Please reach out to the project owner to grant you access. If you have the correct permissions, verify that there are no issues with your networking setup.(Error 404: Not Found)
2024-05-29 17:34:05,535 ERROR   wandb-upload_2:371377 [internal_api.py:execute():373] 404 response executing GraphQL.
2024-05-29 17:34:05,535 ERROR   wandb-upload_2:371377 [internal_api.py:execute():374] {"errors":[{"message":"run StarCraft2_3m/pp602m8s not found during createRunFiles","path":["createRunFiles"]}],"data":{"createRunFiles":null}}
2024-05-29 17:34:05,536 ERROR   Thread-11 :371377 [step_upload.py:_handle_event():200] Failed to upload file: /home/uosai/Desktop/on-policy/onpolicy/scripts/results/StarCraft2/3m/rmappo/Original_Mappo/wandb/run-20240529_173322-pp602m8s/files/requirements.txt
Traceback (most recent call last):
  File "/home/uosai/Desktop/miniconda3/envs/marl/lib/python3.9/site-packages/wandb/sdk/lib/retry.py", line 131, in __call__
    result = self._call_fn(*args, **kwargs)
  File "/home/uosai/Desktop/miniconda3/envs/marl/lib/python3.9/site-packages/wandb/sdk/internal/internal_api.py", line 369, in execute
    return self.client.execute(*args, **kwargs)  # type: ignore
  File "/home/uosai/Desktop/miniconda3/envs/marl/lib/python3.9/site-packages/wandb/vendor/gql-0.2.0/wandb_gql/client.py", line 52, in execute
    result = self._get_result(document, *args, **kwargs)
  File "/home/uosai/Desktop/miniconda3/envs/marl/lib/python3.9/site-packages/wandb/vendor/gql-0.2.0/wandb_gql/client.py", line 60, in _get_result
    return self.transport.execute(document, *args, **kwargs)
  File "/home/uosai/Desktop/miniconda3/envs/marl/lib/python3.9/site-packages/wandb/sdk/lib/gql_request.py", line 59, in execute
    request.raise_for_status()
  File "/home/uosai/Desktop/miniconda3/envs/marl/lib/python3.9/site-packages/requests/models.py", line 1021, in raise_for_status
    raise HTTPError(http_error_msg, response=self)
requests.exceptions.HTTPError: 404 Client Error: Not Found for url: https://api.wandb.ai/graphql

During handling of the above exception, another exception occurred:

Traceback (most recent call last):
  File "/home/uosai/Desktop/miniconda3/envs/marl/lib/python3.9/concurrent/futures/thread.py", line 58, in run
    result = self.fn(*self.args, **self.kwargs)
  File "/home/uosai/Desktop/miniconda3/envs/marl/lib/python3.9/site-packages/wandb/filesync/step_upload.py", line 288, in run_and_notify
    self._do_upload_sync(event)
  File "/home/uosai/Desktop/miniconda3/envs/marl/lib/python3.9/site-packages/wandb/filesync/step_upload.py", line 330, in _do_upload_sync
    job.run()
  File "/home/uosai/Desktop/miniconda3/envs/marl/lib/python3.9/site-packages/wandb/filesync/upload_job.py", line 57, in run
    self.push()
  File "/home/uosai/Desktop/miniconda3/envs/marl/lib/python3.9/site-packages/wandb/filesync/upload_job.py", line 106, in push
    _, upload_headers, result = self._api.upload_urls(project, [self.save_name])
  File "/home/uosai/Desktop/miniconda3/envs/marl/lib/python3.9/site-packages/wandb/apis/normalize.py", line 73, in wrapper
    raise err
  File "/home/uosai/Desktop/miniconda3/envs/marl/lib/python3.9/site-packages/wandb/apis/normalize.py", line 41, in wrapper
    return func(*args, **kwargs)
  File "/home/uosai/Desktop/miniconda3/envs/marl/lib/python3.9/site-packages/wandb/sdk/internal/internal_api.py", line 2384, in upload_urls
    query_result = self.gql(
  File "/home/uosai/Desktop/miniconda3/envs/marl/lib/python3.9/site-packages/wandb/sdk/internal/internal_api.py", line 341, in gql
    ret = self._retry_gql(
  File "/home/uosai/Desktop/miniconda3/envs/marl/lib/python3.9/site-packages/wandb/sdk/lib/retry.py", line 147, in __call__
    retry_timedelta_triggered = check_retry_fn(e)
  File "/home/uosai/Desktop/miniconda3/envs/marl/lib/python3.9/site-packages/wandb/util.py", line 907, in no_retry_auth
    raise CommError(
wandb.errors.CommError: It appears that you do not have permission to access the requested resource. Please reach out to the project owner to grant you access. If you have the correct permissions, verify that there are no issues with your networking setup.(Error 404: Not Found)
2024-05-29 17:34:05,540 ERROR   wandb-upload_4:371377 [internal_api.py:execute():373] 404 response executing GraphQL.
2024-05-29 17:34:05,540 ERROR   wandb-upload_4:371377 [internal_api.py:execute():374] {"errors":[{"message":"run StarCraft2_3m/pp602m8s not found during createRunFiles","path":["createRunFiles"]}],"data":{"createRunFiles":null}}
2024-05-29 17:34:05,540 ERROR   Thread-11 :371377 [step_upload.py:_handle_event():200] Failed to upload file: /home/uosai/Desktop/on-policy/onpolicy/scripts/results/StarCraft2/3m/rmappo/Original_Mappo/wandb/run-20240529_173322-pp602m8s/files/config.yaml
Traceback (most recent call last):
  File "/home/uosai/Desktop/miniconda3/envs/marl/lib/python3.9/site-packages/wandb/sdk/lib/retry.py", line 131, in __call__
    result = self._call_fn(*args, **kwargs)
  File "/home/uosai/Desktop/miniconda3/envs/marl/lib/python3.9/site-packages/wandb/sdk/internal/internal_api.py", line 369, in execute
    return self.client.execute(*args, **kwargs)  # type: ignore
  File "/home/uosai/Desktop/miniconda3/envs/marl/lib/python3.9/site-packages/wandb/vendor/gql-0.2.0/wandb_gql/client.py", line 52, in execute
    result = self._get_result(document, *args, **kwargs)
  File "/home/uosai/Desktop/miniconda3/envs/marl/lib/python3.9/site-packages/wandb/vendor/gql-0.2.0/wandb_gql/client.py", line 60, in _get_result
    return self.transport.execute(document, *args, **kwargs)
  File "/home/uosai/Desktop/miniconda3/envs/marl/lib/python3.9/site-packages/wandb/sdk/lib/gql_request.py", line 59, in execute
    request.raise_for_status()
  File "/home/uosai/Desktop/miniconda3/envs/marl/lib/python3.9/site-packages/requests/models.py", line 1021, in raise_for_status
    raise HTTPError(http_error_msg, response=self)
requests.exceptions.HTTPError: 404 Client Error: Not Found for url: https://api.wandb.ai/graphql

During handling of the above exception, another exception occurred:

Traceback (most recent call last):
  File "/home/uosai/Desktop/miniconda3/envs/marl/lib/python3.9/concurrent/futures/thread.py", line 58, in run
    result = self.fn(*self.args, **self.kwargs)
  File "/home/uosai/Desktop/miniconda3/envs/marl/lib/python3.9/site-packages/wandb/filesync/step_upload.py", line 288, in run_and_notify
    self._do_upload_sync(event)
  File "/home/uosai/Desktop/miniconda3/envs/marl/lib/python3.9/site-packages/wandb/filesync/step_upload.py", line 330, in _do_upload_sync
    job.run()
  File "/home/uosai/Desktop/miniconda3/envs/marl/lib/python3.9/site-packages/wandb/filesync/upload_job.py", line 57, in run
    self.push()
  File "/home/uosai/Desktop/miniconda3/envs/marl/lib/python3.9/site-packages/wandb/filesync/upload_job.py", line 106, in push
    _, upload_headers, result = self._api.upload_urls(project, [self.save_name])
  File "/home/uosai/Desktop/miniconda3/envs/marl/lib/python3.9/site-packages/wandb/apis/normalize.py", line 73, in wrapper
    raise err
  File "/home/uosai/Desktop/miniconda3/envs/marl/lib/python3.9/site-packages/wandb/apis/normalize.py", line 41, in wrapper
    return func(*args, **kwargs)
  File "/home/uosai/Desktop/miniconda3/envs/marl/lib/python3.9/site-packages/wandb/sdk/internal/internal_api.py", line 2384, in upload_urls
    query_result = self.gql(
  File "/home/uosai/Desktop/miniconda3/envs/marl/lib/python3.9/site-packages/wandb/sdk/internal/internal_api.py", line 341, in gql
    ret = self._retry_gql(
  File "/home/uosai/Desktop/miniconda3/envs/marl/lib/python3.9/site-packages/wandb/sdk/lib/retry.py", line 147, in __call__
    retry_timedelta_triggered = check_retry_fn(e)
  File "/home/uosai/Desktop/miniconda3/envs/marl/lib/python3.9/site-packages/wandb/util.py", line 907, in no_retry_auth
    raise CommError(
wandb.errors.CommError: It appears that you do not have permission to access the requested resource. Please reach out to the project owner to grant you access. If you have the correct permissions, verify that there are no issues with your networking setup.(Error 404: Not Found)
2024-05-29 17:34:05,549 ERROR   wandb-upload_5:371377 [internal_api.py:execute():373] 404 response executing GraphQL.
2024-05-29 17:34:05,549 ERROR   wandb-upload_5:371377 [internal_api.py:execute():374] {"errors":[{"message":"run StarCraft2_3m/pp602m8s not found during createRunFiles","path":["createRunFiles"]}],"data":{"createRunFiles":null}}
2024-05-29 17:34:05,549 ERROR   Thread-11 :371377 [step_upload.py:_handle_event():200] Failed to upload file: /home/uosai/Desktop/on-policy/onpolicy/scripts/results/StarCraft2/3m/rmappo/Original_Mappo/wandb/run-20240529_173322-pp602m8s/files/output.log
Traceback (most recent call last):
  File "/home/uosai/Desktop/miniconda3/envs/marl/lib/python3.9/site-packages/wandb/sdk/lib/retry.py", line 131, in __call__
    result = self._call_fn(*args, **kwargs)
  File "/home/uosai/Desktop/miniconda3/envs/marl/lib/python3.9/site-packages/wandb/sdk/internal/internal_api.py", line 369, in execute
    return self.client.execute(*args, **kwargs)  # type: ignore
  File "/home/uosai/Desktop/miniconda3/envs/marl/lib/python3.9/site-packages/wandb/vendor/gql-0.2.0/wandb_gql/client.py", line 52, in execute
    result = self._get_result(document, *args, **kwargs)
  File "/home/uosai/Desktop/miniconda3/envs/marl/lib/python3.9/site-packages/wandb/vendor/gql-0.2.0/wandb_gql/client.py", line 60, in _get_result
    return self.transport.execute(document, *args, **kwargs)
  File "/home/uosai/Desktop/miniconda3/envs/marl/lib/python3.9/site-packages/wandb/sdk/lib/gql_request.py", line 59, in execute
    request.raise_for_status()
  File "/home/uosai/Desktop/miniconda3/envs/marl/lib/python3.9/site-packages/requests/models.py", line 1021, in raise_for_status
    raise HTTPError(http_error_msg, response=self)
requests.exceptions.HTTPError: 404 Client Error: Not Found for url: https://api.wandb.ai/graphql

During handling of the above exception, another exception occurred:

Traceback (most recent call last):
  File "/home/uosai/Desktop/miniconda3/envs/marl/lib/python3.9/concurrent/futures/thread.py", line 58, in run
    result = self.fn(*self.args, **self.kwargs)
  File "/home/uosai/Desktop/miniconda3/envs/marl/lib/python3.9/site-packages/wandb/filesync/step_upload.py", line 288, in run_and_notify
    self._do_upload_sync(event)
  File "/home/uosai/Desktop/miniconda3/envs/marl/lib/python3.9/site-packages/wandb/filesync/step_upload.py", line 330, in _do_upload_sync
    job.run()
  File "/home/uosai/Desktop/miniconda3/envs/marl/lib/python3.9/site-packages/wandb/filesync/upload_job.py", line 57, in run
    self.push()
  File "/home/uosai/Desktop/miniconda3/envs/marl/lib/python3.9/site-packages/wandb/filesync/upload_job.py", line 106, in push
    _, upload_headers, result = self._api.upload_urls(project, [self.save_name])
  File "/home/uosai/Desktop/miniconda3/envs/marl/lib/python3.9/site-packages/wandb/apis/normalize.py", line 73, in wrapper
    raise err
  File "/home/uosai/Desktop/miniconda3/envs/marl/lib/python3.9/site-packages/wandb/apis/normalize.py", line 41, in wrapper
    return func(*args, **kwargs)
  File "/home/uosai/Desktop/miniconda3/envs/marl/lib/python3.9/site-packages/wandb/sdk/internal/internal_api.py", line 2384, in upload_urls
    query_result = self.gql(
  File "/home/uosai/Desktop/miniconda3/envs/marl/lib/python3.9/site-packages/wandb/sdk/internal/internal_api.py", line 341, in gql
    ret = self._retry_gql(
  File "/home/uosai/Desktop/miniconda3/envs/marl/lib/python3.9/site-packages/wandb/sdk/lib/retry.py", line 147, in __call__
    retry_timedelta_triggered = check_retry_fn(e)
  File "/home/uosai/Desktop/miniconda3/envs/marl/lib/python3.9/site-packages/wandb/util.py", line 907, in no_retry_auth
    raise CommError(
wandb.errors.CommError: It appears that you do not have permission to access the requested resource. Please reach out to the project owner to grant you access. If you have the correct permissions, verify that there are no issues with your networking setup.(Error 404: Not Found)
2024-05-29 17:34:05,604 ERROR   wandb-upload_3:371377 [internal_api.py:execute():373] 404 response executing GraphQL.
2024-05-29 17:34:05,604 ERROR   wandb-upload_3:371377 [internal_api.py:execute():374] {"errors":[{"message":"run StarCraft2_3m/pp602m8s not found during createRunFiles","path":["createRunFiles"]}],"data":{"createRunFiles":null}}
2024-05-29 17:34:05,605 ERROR   Thread-11 :371377 [step_upload.py:_handle_event():200] Failed to upload file: /home/uosai/Desktop/on-policy/onpolicy/scripts/results/StarCraft2/3m/rmappo/Original_Mappo/wandb/run-20240529_173322-pp602m8s/files/critic.pt
Traceback (most recent call last):
  File "/home/uosai/Desktop/miniconda3/envs/marl/lib/python3.9/site-packages/wandb/sdk/lib/retry.py", line 131, in __call__
    result = self._call_fn(*args, **kwargs)
  File "/home/uosai/Desktop/miniconda3/envs/marl/lib/python3.9/site-packages/wandb/sdk/internal/internal_api.py", line 369, in execute
    return self.client.execute(*args, **kwargs)  # type: ignore
  File "/home/uosai/Desktop/miniconda3/envs/marl/lib/python3.9/site-packages/wandb/vendor/gql-0.2.0/wandb_gql/client.py", line 52, in execute
    result = self._get_result(document, *args, **kwargs)
  File "/home/uosai/Desktop/miniconda3/envs/marl/lib/python3.9/site-packages/wandb/vendor/gql-0.2.0/wandb_gql/client.py", line 60, in _get_result
    return self.transport.execute(document, *args, **kwargs)
  File "/home/uosai/Desktop/miniconda3/envs/marl/lib/python3.9/site-packages/wandb/sdk/lib/gql_request.py", line 59, in execute
    request.raise_for_status()
  File "/home/uosai/Desktop/miniconda3/envs/marl/lib/python3.9/site-packages/requests/models.py", line 1021, in raise_for_status
    raise HTTPError(http_error_msg, response=self)
requests.exceptions.HTTPError: 404 Client Error: Not Found for url: https://api.wandb.ai/graphql

During handling of the above exception, another exception occurred:

Traceback (most recent call last):
  File "/home/uosai/Desktop/miniconda3/envs/marl/lib/python3.9/concurrent/futures/thread.py", line 58, in run
    result = self.fn(*self.args, **self.kwargs)
  File "/home/uosai/Desktop/miniconda3/envs/marl/lib/python3.9/site-packages/wandb/filesync/step_upload.py", line 288, in run_and_notify
    self._do_upload_sync(event)
  File "/home/uosai/Desktop/miniconda3/envs/marl/lib/python3.9/site-packages/wandb/filesync/step_upload.py", line 330, in _do_upload_sync
    job.run()
  File "/home/uosai/Desktop/miniconda3/envs/marl/lib/python3.9/site-packages/wandb/filesync/upload_job.py", line 57, in run
    self.push()
  File "/home/uosai/Desktop/miniconda3/envs/marl/lib/python3.9/site-packages/wandb/filesync/upload_job.py", line 106, in push
    _, upload_headers, result = self._api.upload_urls(project, [self.save_name])
  File "/home/uosai/Desktop/miniconda3/envs/marl/lib/python3.9/site-packages/wandb/apis/normalize.py", line 73, in wrapper
    raise err
  File "/home/uosai/Desktop/miniconda3/envs/marl/lib/python3.9/site-packages/wandb/apis/normalize.py", line 41, in wrapper
    return func(*args, **kwargs)
  File "/home/uosai/Desktop/miniconda3/envs/marl/lib/python3.9/site-packages/wandb/sdk/internal/internal_api.py", line 2384, in upload_urls
    query_result = self.gql(
  File "/home/uosai/Desktop/miniconda3/envs/marl/lib/python3.9/site-packages/wandb/sdk/internal/internal_api.py", line 341, in gql
    ret = self._retry_gql(
  File "/home/uosai/Desktop/miniconda3/envs/marl/lib/python3.9/site-packages/wandb/sdk/lib/retry.py", line 147, in __call__
    retry_timedelta_triggered = check_retry_fn(e)
  File "/home/uosai/Desktop/miniconda3/envs/marl/lib/python3.9/site-packages/wandb/util.py", line 907, in no_retry_auth
    raise CommError(
wandb.errors.CommError: It appears that you do not have permission to access the requested resource. Please reach out to the project owner to grant you access. If you have the correct permissions, verify that there are no issues with your networking setup.(Error 404: Not Found)
2024-05-29 17:34:05,605 INFO    MainThread:371377 [internal.py:handle_exit():76] Internal process exited
