2024-05-29 17:33:22,774 INFO    StreamThr :371541 [internal.py:wandb_internal():86] W&B internal server running at pid: 371541, started at: 2024-05-29 17:33:22.773861
2024-05-29 17:33:22,775 DEBUG   HandlerThread:371541 [handler.py:handle_request():146] handle_request: status
2024-05-29 17:33:22,779 INFO    WriterThread:371541 [datastore.py:open_for_write():87] open: /home/uosai/Desktop/on-policy/onpolicy/scripts/results/StarCraft2/3m/rmappo/Original_Mappo/wandb/run-20240529_173322-yno7tz4a/run-yno7tz4a.wandb
2024-05-29 17:33:22,780 DEBUG   SenderThread:371541 [sender.py:send():382] send: header
2024-05-29 17:33:22,799 DEBUG   SenderThread:371541 [sender.py:send():382] send: run
2024-05-29 17:33:23,320 INFO    SenderThread:371541 [dir_watcher.py:__init__():211] watching files in: /home/uosai/Desktop/on-policy/onpolicy/scripts/results/StarCraft2/3m/rmappo/Original_Mappo/wandb/run-20240529_173322-yno7tz4a/files
2024-05-29 17:33:23,320 INFO    SenderThread:371541 [sender.py:_start_run_threads():1136] run started: yno7tz4a with start time 1716971602.774103
2024-05-29 17:33:23,329 DEBUG   HandlerThread:371541 [handler.py:handle_request():146] handle_request: check_version
2024-05-29 17:33:23,329 DEBUG   SenderThread:371541 [sender.py:send_request():409] send_request: check_version
2024-05-29 17:33:23,379 DEBUG   HandlerThread:371541 [handler.py:handle_request():146] handle_request: run_start
2024-05-29 17:33:23,390 DEBUG   HandlerThread:371541 [system_info.py:__init__():27] System info init
2024-05-29 17:33:23,390 DEBUG   HandlerThread:371541 [system_info.py:__init__():42] System info init done
2024-05-29 17:33:23,390 INFO    HandlerThread:371541 [system_monitor.py:start():194] Starting system monitor
2024-05-29 17:33:23,390 INFO    SystemMonitor:371541 [system_monitor.py:_start():158] Starting system asset monitoring threads
2024-05-29 17:33:23,391 INFO    HandlerThread:371541 [system_monitor.py:probe():214] Collecting system info
2024-05-29 17:33:23,391 INFO    SystemMonitor:371541 [interfaces.py:start():190] Started cpu monitoring
2024-05-29 17:33:23,392 INFO    SystemMonitor:371541 [interfaces.py:start():190] Started disk monitoring
2024-05-29 17:33:23,393 INFO    SystemMonitor:371541 [interfaces.py:start():190] Started gpu monitoring
2024-05-29 17:33:23,393 INFO    SystemMonitor:371541 [interfaces.py:start():190] Started memory monitoring
2024-05-29 17:33:23,394 INFO    SystemMonitor:371541 [interfaces.py:start():190] Started network monitoring
2024-05-29 17:33:23,404 DEBUG   HandlerThread:371541 [system_info.py:probe():151] Probing system
2024-05-29 17:33:23,412 DEBUG   HandlerThread:371541 [system_info.py:_probe_git():136] Probing git
2024-05-29 17:33:23,429 DEBUG   HandlerThread:371541 [system_info.py:_probe_git():144] Probing git done
2024-05-29 17:33:23,429 DEBUG   HandlerThread:371541 [system_info.py:probe():199] Probing system done
2024-05-29 17:33:23,429 DEBUG   HandlerThread:371541 [system_monitor.py:probe():223] {'os': 'Linux-6.5.0-35-generic-x86_64-with-glibc2.35', 'python': '3.9.18', 'heartbeatAt': '2024-05-29T08:33:23.404582', 'startedAt': '2024-05-29T08:33:22.768801', 'docker': None, 'cuda': None, 'args': ('--seed', '250', '--env_name', 'StarCraft2', '--experiment_name', 'Original_Mappo', '--group_name', 'Original', '--use_reward_shaping', '--map_name', '3m', '--num_gpu', '0'), 'state': 'running', 'program': '/home/uosai/Desktop/on-policy/onpolicy/scripts/train/train_smac.py', 'codePathLocal': 'train_smac.py', 'codePath': 'onpolicy/scripts/train/train_smac.py', 'git': {'remote': 'https://github.com/singforai/on-policy.git', 'commit': '14d4b373e79555e79221655c211e9561875c023b'}, 'email': 'singfor7012@gmail.com', 'root': '/home/uosai/Desktop/on-policy', 'host': 'uos-desktop', 'username': 'uosai', 'executable': '/home/uosai/Desktop/miniconda3/envs/marl/bin/python', 'cpu_count': 12, 'cpu_count_logical': 24, 'cpu_freq': {'current': 4373.215208333333, 'min': 2200.0, 'max': 3700.0}, 'cpu_freq_per_core': [{'current': 4385.317, 'min': 2200.0, 'max': 3700.0}, {'current': 4389.704, 'min': 2200.0, 'max': 3700.0}, {'current': 4385.323, 'min': 2200.0, 'max': 3700.0}, {'current': 4388.483, 'min': 2200.0, 'max': 3700.0}, {'current': 4384.919, 'min': 2200.0, 'max': 3700.0}, {'current': 3518.732, 'min': 2200.0, 'max': 3700.0}, {'current': 4381.051, 'min': 2200.0, 'max': 3700.0}, {'current': 4367.105, 'min': 2200.0, 'max': 3700.0}, {'current': 4385.333, 'min': 2200.0, 'max': 3700.0}, {'current': 3968.055, 'min': 2200.0, 'max': 3700.0}, {'current': 4383.36, 'min': 2200.0, 'max': 3700.0}, {'current': 4384.539, 'min': 2200.0, 'max': 3700.0}, {'current': 4382.749, 'min': 2200.0, 'max': 3700.0}, {'current': 4385.33, 'min': 2200.0, 'max': 3700.0}, {'current': 4390.924, 'min': 2200.0, 'max': 3700.0}, {'current': 4382.782, 'min': 2200.0, 'max': 3700.0}, {'current': 4391.653, 'min': 2200.0, 'max': 3700.0}, {'current': 3742.035, 'min': 2200.0, 'max': 3700.0}, {'current': 4387.358, 'min': 2200.0, 'max': 3700.0}, {'current': 4339.712, 'min': 2200.0, 'max': 3700.0}, {'current': 4385.334, 'min': 2200.0, 'max': 3700.0}, {'current': 4045.917, 'min': 2200.0, 'max': 3700.0}, {'current': 4389.103, 'min': 2200.0, 'max': 3700.0}, {'current': 4385.33, 'min': 2200.0, 'max': 3700.0}], 'disk': {'/': {'total': 233.17998886108398, 'used': 189.8166961669922}}, 'gpu': 'NVIDIA GeForce RTX 3080', 'gpu_count': 2, 'gpu_devices': [{'name': 'NVIDIA GeForce RTX 3080', 'memory_total': 10737418240}, {'name': 'NVIDIA GeForce RTX 3080', 'memory_total': 10737418240}], 'memory': {'total': 62.709049224853516}}
2024-05-29 17:33:23,430 INFO    HandlerThread:371541 [system_monitor.py:probe():224] Finished collecting system info
2024-05-29 17:33:23,430 INFO    HandlerThread:371541 [system_monitor.py:probe():227] Publishing system info
2024-05-29 17:33:23,430 DEBUG   HandlerThread:371541 [system_info.py:_save_conda():208] Saving list of conda packages installed into the current environment
2024-05-29 17:33:24,323 INFO    Thread-12 :371541 [dir_watcher.py:_on_file_created():271] file/dir created: /home/uosai/Desktop/on-policy/onpolicy/scripts/results/StarCraft2/3m/rmappo/Original_Mappo/wandb/run-20240529_173322-yno7tz4a/files/conda-environment.yaml
2024-05-29 17:33:26,271 DEBUG   HandlerThread:371541 [system_info.py:_save_conda():220] Saving conda packages done
2024-05-29 17:33:26,272 INFO    HandlerThread:371541 [system_monitor.py:probe():229] Finished publishing system info
2024-05-29 17:33:26,275 DEBUG   SenderThread:371541 [sender.py:send():382] send: files
2024-05-29 17:33:26,276 INFO    SenderThread:371541 [sender.py:_save_file():1403] saving file wandb-metadata.json with policy now
2024-05-29 17:33:26,292 DEBUG   HandlerThread:371541 [handler.py:handle_request():146] handle_request: python_packages
2024-05-29 17:33:26,293 DEBUG   SenderThread:371541 [sender.py:send_request():409] send_request: python_packages
2024-05-29 17:33:26,294 DEBUG   HandlerThread:371541 [handler.py:handle_request():146] handle_request: stop_status
2024-05-29 17:33:26,294 DEBUG   SenderThread:371541 [sender.py:send_request():409] send_request: stop_status
2024-05-29 17:33:26,307 DEBUG   HandlerThread:371541 [handler.py:handle_request():146] handle_request: internal_messages
2024-05-29 17:33:26,322 INFO    Thread-12 :371541 [dir_watcher.py:_on_file_modified():288] file/dir modified: /home/uosai/Desktop/on-policy/onpolicy/scripts/results/StarCraft2/3m/rmappo/Original_Mappo/wandb/run-20240529_173322-yno7tz4a/files/conda-environment.yaml
2024-05-29 17:33:26,322 INFO    Thread-12 :371541 [dir_watcher.py:_on_file_created():271] file/dir created: /home/uosai/Desktop/on-policy/onpolicy/scripts/results/StarCraft2/3m/rmappo/Original_Mappo/wandb/run-20240529_173322-yno7tz4a/files/requirements.txt
2024-05-29 17:33:26,322 INFO    Thread-12 :371541 [dir_watcher.py:_on_file_created():271] file/dir created: /home/uosai/Desktop/on-policy/onpolicy/scripts/results/StarCraft2/3m/rmappo/Original_Mappo/wandb/run-20240529_173322-yno7tz4a/files/wandb-metadata.json
2024-05-29 17:33:26,597 DEBUG   SenderThread:371541 [sender.py:send():382] send: telemetry
2024-05-29 17:33:27,071 INFO    wandb-upload_0:371541 [upload_job.py:push():131] Uploaded file /tmp/tmpekcz_r25wandb/35brcsok-wandb-metadata.json
2024-05-29 17:33:27,214 DEBUG   SenderThread:371541 [sender.py:send():382] send: telemetry
2024-05-29 17:33:27,445 DEBUG   SenderThread:371541 [sender.py:send():382] send: telemetry
2024-05-29 17:33:28,445 DEBUG   HandlerThread:371541 [handler.py:handle_request():146] handle_request: status_report
2024-05-29 17:33:33,446 DEBUG   HandlerThread:371541 [handler.py:handle_request():146] handle_request: status_report
2024-05-29 17:33:35,324 INFO    Thread-12 :371541 [dir_watcher.py:_on_file_created():271] file/dir created: /home/uosai/Desktop/on-policy/onpolicy/scripts/results/StarCraft2/3m/rmappo/Original_Mappo/wandb/run-20240529_173322-yno7tz4a/files/output.log
2024-05-29 17:33:36,805 DEBUG   HandlerThread:371541 [handler.py:handle_request():146] handle_request: partial_history
2024-05-29 17:33:36,806 DEBUG   HandlerThread:371541 [handler.py:handle_request():146] handle_request: partial_history
2024-05-29 17:33:36,806 DEBUG   HandlerThread:371541 [handler.py:handle_request():146] handle_request: partial_history
2024-05-29 17:33:36,806 DEBUG   HandlerThread:371541 [handler.py:handle_request():146] handle_request: partial_history
2024-05-29 17:33:37,173 DEBUG   HandlerThread:371541 [handler.py:handle_request():146] handle_request: partial_history
2024-05-29 17:33:37,174 DEBUG   HandlerThread:371541 [handler.py:handle_request():146] handle_request: partial_history
2024-05-29 17:33:37,174 DEBUG   HandlerThread:371541 [handler.py:handle_request():146] handle_request: partial_history
2024-05-29 17:33:37,174 DEBUG   HandlerThread:371541 [handler.py:handle_request():146] handle_request: partial_history
2024-05-29 17:33:37,174 DEBUG   HandlerThread:371541 [handler.py:handle_request():146] handle_request: partial_history
2024-05-29 17:33:37,325 INFO    Thread-12 :371541 [dir_watcher.py:_on_file_modified():288] file/dir modified: /home/uosai/Desktop/on-policy/onpolicy/scripts/results/StarCraft2/3m/rmappo/Original_Mappo/wandb/run-20240529_173322-yno7tz4a/files/output.log
2024-05-29 17:33:37,326 INFO    Thread-12 :371541 [dir_watcher.py:_on_file_created():271] file/dir created: /home/uosai/Desktop/on-policy/onpolicy/scripts/results/StarCraft2/3m/rmappo/Original_Mappo/wandb/run-20240529_173322-yno7tz4a/files/critic.pt
2024-05-29 17:33:37,326 INFO    Thread-12 :371541 [dir_watcher.py:_on_file_created():271] file/dir created: /home/uosai/Desktop/on-policy/onpolicy/scripts/results/StarCraft2/3m/rmappo/Original_Mappo/wandb/run-20240529_173322-yno7tz4a/files/actor.pt
2024-05-29 17:33:39,174 DEBUG   HandlerThread:371541 [handler.py:handle_request():146] handle_request: status_report
2024-05-29 17:33:39,326 INFO    Thread-12 :371541 [dir_watcher.py:_on_file_modified():288] file/dir modified: /home/uosai/Desktop/on-policy/onpolicy/scripts/results/StarCraft2/3m/rmappo/Original_Mappo/wandb/run-20240529_173322-yno7tz4a/files/output.log
2024-05-29 17:33:41,295 DEBUG   HandlerThread:371541 [handler.py:handle_request():146] handle_request: stop_status
2024-05-29 17:33:41,295 DEBUG   SenderThread:371541 [sender.py:send_request():409] send_request: stop_status
2024-05-29 17:33:41,299 DEBUG   HandlerThread:371541 [handler.py:handle_request():146] handle_request: internal_messages
2024-05-29 17:33:43,444 DEBUG   HandlerThread:371541 [handler.py:handle_request():146] handle_request: partial_history
2024-05-29 17:33:43,445 DEBUG   HandlerThread:371541 [handler.py:handle_request():146] handle_request: partial_history
2024-05-29 17:33:44,445 DEBUG   HandlerThread:371541 [handler.py:handle_request():146] handle_request: status_report
2024-05-29 17:33:45,328 INFO    Thread-12 :371541 [dir_watcher.py:_on_file_modified():288] file/dir modified: /home/uosai/Desktop/on-policy/onpolicy/scripts/results/StarCraft2/3m/rmappo/Original_Mappo/wandb/run-20240529_173322-yno7tz4a/files/output.log
2024-05-29 17:33:49,446 DEBUG   HandlerThread:371541 [handler.py:handle_request():146] handle_request: status_report
2024-05-29 17:33:54,451 DEBUG   HandlerThread:371541 [handler.py:handle_request():146] handle_request: status_report
2024-05-29 17:33:55,331 INFO    Thread-12 :371541 [dir_watcher.py:_on_file_modified():288] file/dir modified: /home/uosai/Desktop/on-policy/onpolicy/scripts/results/StarCraft2/3m/rmappo/Original_Mappo/wandb/run-20240529_173322-yno7tz4a/files/config.yaml
2024-05-29 17:33:56,294 DEBUG   HandlerThread:371541 [handler.py:handle_request():146] handle_request: stop_status
2024-05-29 17:33:56,295 DEBUG   SenderThread:371541 [sender.py:send_request():409] send_request: stop_status
2024-05-29 17:33:56,300 DEBUG   HandlerThread:371541 [handler.py:handle_request():146] handle_request: internal_messages
2024-05-29 17:34:00,573 DEBUG   HandlerThread:371541 [handler.py:handle_request():146] handle_request: status_report
2024-05-29 17:34:03,410 INFO    memory    :371541 [interfaces.py:monitor():140] Process proc.memory.rssMB has exited.
2024-05-29 17:34:03,411 DEBUG   SystemMonitor:371541 [system_monitor.py:_start():172] Starting system metrics aggregation loop
2024-05-29 17:34:03,411 DEBUG   SystemMonitor:371541 [system_monitor.py:_start():179] Finished system metrics aggregation loop
2024-05-29 17:34:03,411 DEBUG   SystemMonitor:371541 [system_monitor.py:_start():183] Publishing last batch of metrics
2024-05-29 17:34:03,412 DEBUG   SenderThread:371541 [sender.py:send():382] send: stats
2024-05-29 17:34:03,604 ERROR   FileStreamThread:371541 [file_stream.py:_handle_response():504] dropped chunk 404 Client Error: Not Found for url: https://api.wandb.ai/files/singfor7012/StarCraft2_3m/yno7tz4a/file_stream
NoneType: None
2024-05-29 17:34:03,816 WARNING StreamThr :371541 [internal.py:is_dead():414] Internal process exiting, parent pid 370843 disappeared
2024-05-29 17:34:03,817 ERROR   StreamThr :371541 [internal.py:wandb_internal():152] Internal process shutdown.
2024-05-29 17:34:04,412 INFO    HandlerThread:371541 [handler.py:finish():869] shutting down handler
2024-05-29 17:34:04,412 INFO    HandlerThread:371541 [system_monitor.py:finish():203] Stopping system monitor
2024-05-29 17:34:04,412 INFO    HandlerThread:371541 [interfaces.py:finish():202] Joined cpu monitor
2024-05-29 17:34:04,412 INFO    WriterThread:371541 [datastore.py:close():296] close: /home/uosai/Desktop/on-policy/onpolicy/scripts/results/StarCraft2/3m/rmappo/Original_Mappo/wandb/run-20240529_173322-yno7tz4a/run-yno7tz4a.wandb
2024-05-29 17:34:04,412 INFO    HandlerThread:371541 [interfaces.py:finish():202] Joined disk monitor
2024-05-29 17:34:04,413 INFO    HandlerThread:371541 [interfaces.py:finish():202] Joined gpu monitor
2024-05-29 17:34:04,413 INFO    HandlerThread:371541 [interfaces.py:finish():202] Joined memory monitor
2024-05-29 17:34:04,413 INFO    HandlerThread:371541 [interfaces.py:finish():202] Joined network monitor
2024-05-29 17:34:04,413 INFO    SenderThread:371541 [sender.py:finish():1572] shutting down sender
2024-05-29 17:34:04,836 INFO    SenderThread:371541 [dir_watcher.py:finish():358] shutting down directory watcher
2024-05-29 17:34:05,335 INFO    SenderThread:371541 [dir_watcher.py:_on_file_modified():288] file/dir modified: /home/uosai/Desktop/on-policy/onpolicy/scripts/results/StarCraft2/3m/rmappo/Original_Mappo/wandb/run-20240529_173322-yno7tz4a/files/output.log
2024-05-29 17:34:05,335 INFO    SenderThread:371541 [dir_watcher.py:finish():388] scan: /home/uosai/Desktop/on-policy/onpolicy/scripts/results/StarCraft2/3m/rmappo/Original_Mappo/wandb/run-20240529_173322-yno7tz4a/files
2024-05-29 17:34:05,336 INFO    SenderThread:371541 [dir_watcher.py:finish():402] scan save: /home/uosai/Desktop/on-policy/onpolicy/scripts/results/StarCraft2/3m/rmappo/Original_Mappo/wandb/run-20240529_173322-yno7tz4a/files/actor.pt actor.pt
2024-05-29 17:34:05,336 INFO    SenderThread:371541 [dir_watcher.py:finish():402] scan save: /home/uosai/Desktop/on-policy/onpolicy/scripts/results/StarCraft2/3m/rmappo/Original_Mappo/wandb/run-20240529_173322-yno7tz4a/files/conda-environment.yaml conda-environment.yaml
2024-05-29 17:34:05,337 INFO    SenderThread:371541 [dir_watcher.py:finish():402] scan save: /home/uosai/Desktop/on-policy/onpolicy/scripts/results/StarCraft2/3m/rmappo/Original_Mappo/wandb/run-20240529_173322-yno7tz4a/files/requirements.txt requirements.txt
2024-05-29 17:34:05,340 INFO    SenderThread:371541 [dir_watcher.py:finish():402] scan save: /home/uosai/Desktop/on-policy/onpolicy/scripts/results/StarCraft2/3m/rmappo/Original_Mappo/wandb/run-20240529_173322-yno7tz4a/files/critic.pt critic.pt
2024-05-29 17:34:05,341 INFO    SenderThread:371541 [dir_watcher.py:finish():402] scan save: /home/uosai/Desktop/on-policy/onpolicy/scripts/results/StarCraft2/3m/rmappo/Original_Mappo/wandb/run-20240529_173322-yno7tz4a/files/config.yaml config.yaml
2024-05-29 17:34:05,342 INFO    SenderThread:371541 [dir_watcher.py:finish():402] scan save: /home/uosai/Desktop/on-policy/onpolicy/scripts/results/StarCraft2/3m/rmappo/Original_Mappo/wandb/run-20240529_173322-yno7tz4a/files/wandb-metadata.json wandb-metadata.json
2024-05-29 17:34:05,343 INFO    SenderThread:371541 [dir_watcher.py:finish():402] scan save: /home/uosai/Desktop/on-policy/onpolicy/scripts/results/StarCraft2/3m/rmappo/Original_Mappo/wandb/run-20240529_173322-yno7tz4a/files/output.log output.log
2024-05-29 17:34:05,344 INFO    SenderThread:371541 [file_pusher.py:finish():175] shutting down file pusher
2024-05-29 17:34:05,344 INFO    SenderThread:371541 [file_pusher.py:join():181] waiting for file pusher
2024-05-29 17:34:05,529 ERROR   wandb-upload_0:371541 [internal_api.py:execute():373] 404 response executing GraphQL.
2024-05-29 17:34:05,529 ERROR   wandb-upload_0:371541 [internal_api.py:execute():374] {"errors":[{"message":"run StarCraft2_3m/yno7tz4a not found during createRunFiles","path":["createRunFiles"]}],"data":{"createRunFiles":null}}
2024-05-29 17:34:05,529 ERROR   Thread-11 :371541 [step_upload.py:_handle_event():200] Failed to upload file: /home/uosai/Desktop/on-policy/onpolicy/scripts/results/StarCraft2/3m/rmappo/Original_Mappo/wandb/run-20240529_173322-yno7tz4a/files/actor.pt
Traceback (most recent call last):
  File "/home/uosai/Desktop/miniconda3/envs/marl/lib/python3.9/site-packages/wandb/sdk/lib/retry.py", line 131, in __call__
    result = self._call_fn(*args, **kwargs)
  File "/home/uosai/Desktop/miniconda3/envs/marl/lib/python3.9/site-packages/wandb/sdk/internal/internal_api.py", line 369, in execute
    return self.client.execute(*args, **kwargs)  # type: ignore
  File "/home/uosai/Desktop/miniconda3/envs/marl/lib/python3.9/site-packages/wandb/vendor/gql-0.2.0/wandb_gql/client.py", line 52, in execute
    result = self._get_result(document, *args, **kwargs)
  File "/home/uosai/Desktop/miniconda3/envs/marl/lib/python3.9/site-packages/wandb/vendor/gql-0.2.0/wandb_gql/client.py", line 60, in _get_result
    return self.transport.execute(document, *args, **kwargs)
  File "/home/uosai/Desktop/miniconda3/envs/marl/lib/python3.9/site-packages/wandb/sdk/lib/gql_request.py", line 59, in execute
    request.raise_for_status()
  File "/home/uosai/Desktop/miniconda3/envs/marl/lib/python3.9/site-packages/requests/models.py", line 1021, in raise_for_status
    raise HTTPError(http_error_msg, response=self)
requests.exceptions.HTTPError: 404 Client Error: Not Found for url: https://api.wandb.ai/graphql

During handling of the above exception, another exception occurred:

Traceback (most recent call last):
  File "/home/uosai/Desktop/miniconda3/envs/marl/lib/python3.9/concurrent/futures/thread.py", line 58, in run
    result = self.fn(*self.args, **self.kwargs)
  File "/home/uosai/Desktop/miniconda3/envs/marl/lib/python3.9/site-packages/wandb/filesync/step_upload.py", line 288, in run_and_notify
    self._do_upload_sync(event)
  File "/home/uosai/Desktop/miniconda3/envs/marl/lib/python3.9/site-packages/wandb/filesync/step_upload.py", line 330, in _do_upload_sync
    job.run()
  File "/home/uosai/Desktop/miniconda3/envs/marl/lib/python3.9/site-packages/wandb/filesync/upload_job.py", line 57, in run
    self.push()
  File "/home/uosai/Desktop/miniconda3/envs/marl/lib/python3.9/site-packages/wandb/filesync/upload_job.py", line 106, in push
    _, upload_headers, result = self._api.upload_urls(project, [self.save_name])
  File "/home/uosai/Desktop/miniconda3/envs/marl/lib/python3.9/site-packages/wandb/apis/normalize.py", line 73, in wrapper
    raise err
  File "/home/uosai/Desktop/miniconda3/envs/marl/lib/python3.9/site-packages/wandb/apis/normalize.py", line 41, in wrapper
    return func(*args, **kwargs)
  File "/home/uosai/Desktop/miniconda3/envs/marl/lib/python3.9/site-packages/wandb/sdk/internal/internal_api.py", line 2384, in upload_urls
    query_result = self.gql(
  File "/home/uosai/Desktop/miniconda3/envs/marl/lib/python3.9/site-packages/wandb/sdk/internal/internal_api.py", line 341, in gql
    ret = self._retry_gql(
  File "/home/uosai/Desktop/miniconda3/envs/marl/lib/python3.9/site-packages/wandb/sdk/lib/retry.py", line 147, in __call__
    retry_timedelta_triggered = check_retry_fn(e)
  File "/home/uosai/Desktop/miniconda3/envs/marl/lib/python3.9/site-packages/wandb/util.py", line 907, in no_retry_auth
    raise CommError(
wandb.errors.CommError: It appears that you do not have permission to access the requested resource. Please reach out to the project owner to grant you access. If you have the correct permissions, verify that there are no issues with your networking setup.(Error 404: Not Found)
2024-05-29 17:34:05,541 ERROR   wandb-upload_1:371541 [internal_api.py:execute():373] 404 response executing GraphQL.
2024-05-29 17:34:05,541 ERROR   wandb-upload_1:371541 [internal_api.py:execute():374] {"errors":[{"message":"run StarCraft2_3m/yno7tz4a not found during createRunFiles","path":["createRunFiles"]}],"data":{"createRunFiles":null}}
2024-05-29 17:34:05,542 ERROR   Thread-11 :371541 [step_upload.py:_handle_event():200] Failed to upload file: /home/uosai/Desktop/on-policy/onpolicy/scripts/results/StarCraft2/3m/rmappo/Original_Mappo/wandb/run-20240529_173322-yno7tz4a/files/conda-environment.yaml
Traceback (most recent call last):
  File "/home/uosai/Desktop/miniconda3/envs/marl/lib/python3.9/site-packages/wandb/sdk/lib/retry.py", line 131, in __call__
    result = self._call_fn(*args, **kwargs)
  File "/home/uosai/Desktop/miniconda3/envs/marl/lib/python3.9/site-packages/wandb/sdk/internal/internal_api.py", line 369, in execute
    return self.client.execute(*args, **kwargs)  # type: ignore
  File "/home/uosai/Desktop/miniconda3/envs/marl/lib/python3.9/site-packages/wandb/vendor/gql-0.2.0/wandb_gql/client.py", line 52, in execute
    result = self._get_result(document, *args, **kwargs)
  File "/home/uosai/Desktop/miniconda3/envs/marl/lib/python3.9/site-packages/wandb/vendor/gql-0.2.0/wandb_gql/client.py", line 60, in _get_result
    return self.transport.execute(document, *args, **kwargs)
  File "/home/uosai/Desktop/miniconda3/envs/marl/lib/python3.9/site-packages/wandb/sdk/lib/gql_request.py", line 59, in execute
    request.raise_for_status()
  File "/home/uosai/Desktop/miniconda3/envs/marl/lib/python3.9/site-packages/requests/models.py", line 1021, in raise_for_status
    raise HTTPError(http_error_msg, response=self)
requests.exceptions.HTTPError: 404 Client Error: Not Found for url: https://api.wandb.ai/graphql

During handling of the above exception, another exception occurred:

Traceback (most recent call last):
  File "/home/uosai/Desktop/miniconda3/envs/marl/lib/python3.9/concurrent/futures/thread.py", line 58, in run
    result = self.fn(*self.args, **self.kwargs)
  File "/home/uosai/Desktop/miniconda3/envs/marl/lib/python3.9/site-packages/wandb/filesync/step_upload.py", line 288, in run_and_notify
    self._do_upload_sync(event)
  File "/home/uosai/Desktop/miniconda3/envs/marl/lib/python3.9/site-packages/wandb/filesync/step_upload.py", line 330, in _do_upload_sync
    job.run()
  File "/home/uosai/Desktop/miniconda3/envs/marl/lib/python3.9/site-packages/wandb/filesync/upload_job.py", line 57, in run
    self.push()
  File "/home/uosai/Desktop/miniconda3/envs/marl/lib/python3.9/site-packages/wandb/filesync/upload_job.py", line 106, in push
    _, upload_headers, result = self._api.upload_urls(project, [self.save_name])
  File "/home/uosai/Desktop/miniconda3/envs/marl/lib/python3.9/site-packages/wandb/apis/normalize.py", line 73, in wrapper
    raise err
  File "/home/uosai/Desktop/miniconda3/envs/marl/lib/python3.9/site-packages/wandb/apis/normalize.py", line 41, in wrapper
    return func(*args, **kwargs)
  File "/home/uosai/Desktop/miniconda3/envs/marl/lib/python3.9/site-packages/wandb/sdk/internal/internal_api.py", line 2384, in upload_urls
    query_result = self.gql(
  File "/home/uosai/Desktop/miniconda3/envs/marl/lib/python3.9/site-packages/wandb/sdk/internal/internal_api.py", line 341, in gql
    ret = self._retry_gql(
  File "/home/uosai/Desktop/miniconda3/envs/marl/lib/python3.9/site-packages/wandb/sdk/lib/retry.py", line 147, in __call__
    retry_timedelta_triggered = check_retry_fn(e)
  File "/home/uosai/Desktop/miniconda3/envs/marl/lib/python3.9/site-packages/wandb/util.py", line 907, in no_retry_auth
    raise CommError(
wandb.errors.CommError: It appears that you do not have permission to access the requested resource. Please reach out to the project owner to grant you access. If you have the correct permissions, verify that there are no issues with your networking setup.(Error 404: Not Found)
2024-05-29 17:34:05,552 ERROR   wandb-upload_4:371541 [internal_api.py:execute():373] 404 response executing GraphQL.
2024-05-29 17:34:05,552 ERROR   wandb-upload_4:371541 [internal_api.py:execute():374] {"errors":[{"message":"run StarCraft2_3m/yno7tz4a not found during createRunFiles","path":["createRunFiles"]}],"data":{"createRunFiles":null}}
2024-05-29 17:34:05,553 ERROR   Thread-11 :371541 [step_upload.py:_handle_event():200] Failed to upload file: /home/uosai/Desktop/on-policy/onpolicy/scripts/results/StarCraft2/3m/rmappo/Original_Mappo/wandb/run-20240529_173322-yno7tz4a/files/config.yaml
Traceback (most recent call last):
  File "/home/uosai/Desktop/miniconda3/envs/marl/lib/python3.9/site-packages/wandb/sdk/lib/retry.py", line 131, in __call__
    result = self._call_fn(*args, **kwargs)
  File "/home/uosai/Desktop/miniconda3/envs/marl/lib/python3.9/site-packages/wandb/sdk/internal/internal_api.py", line 369, in execute
    return self.client.execute(*args, **kwargs)  # type: ignore
  File "/home/uosai/Desktop/miniconda3/envs/marl/lib/python3.9/site-packages/wandb/vendor/gql-0.2.0/wandb_gql/client.py", line 52, in execute
    result = self._get_result(document, *args, **kwargs)
  File "/home/uosai/Desktop/miniconda3/envs/marl/lib/python3.9/site-packages/wandb/vendor/gql-0.2.0/wandb_gql/client.py", line 60, in _get_result
    return self.transport.execute(document, *args, **kwargs)
  File "/home/uosai/Desktop/miniconda3/envs/marl/lib/python3.9/site-packages/wandb/sdk/lib/gql_request.py", line 59, in execute
    request.raise_for_status()
  File "/home/uosai/Desktop/miniconda3/envs/marl/lib/python3.9/site-packages/requests/models.py", line 1021, in raise_for_status
    raise HTTPError(http_error_msg, response=self)
requests.exceptions.HTTPError: 404 Client Error: Not Found for url: https://api.wandb.ai/graphql

During handling of the above exception, another exception occurred:

Traceback (most recent call last):
  File "/home/uosai/Desktop/miniconda3/envs/marl/lib/python3.9/concurrent/futures/thread.py", line 58, in run
    result = self.fn(*self.args, **self.kwargs)
  File "/home/uosai/Desktop/miniconda3/envs/marl/lib/python3.9/site-packages/wandb/filesync/step_upload.py", line 288, in run_and_notify
    self._do_upload_sync(event)
  File "/home/uosai/Desktop/miniconda3/envs/marl/lib/python3.9/site-packages/wandb/filesync/step_upload.py", line 330, in _do_upload_sync
    job.run()
  File "/home/uosai/Desktop/miniconda3/envs/marl/lib/python3.9/site-packages/wandb/filesync/upload_job.py", line 57, in run
    self.push()
  File "/home/uosai/Desktop/miniconda3/envs/marl/lib/python3.9/site-packages/wandb/filesync/upload_job.py", line 106, in push
    _, upload_headers, result = self._api.upload_urls(project, [self.save_name])
  File "/home/uosai/Desktop/miniconda3/envs/marl/lib/python3.9/site-packages/wandb/apis/normalize.py", line 73, in wrapper
    raise err
  File "/home/uosai/Desktop/miniconda3/envs/marl/lib/python3.9/site-packages/wandb/apis/normalize.py", line 41, in wrapper
    return func(*args, **kwargs)
  File "/home/uosai/Desktop/miniconda3/envs/marl/lib/python3.9/site-packages/wandb/sdk/internal/internal_api.py", line 2384, in upload_urls
    query_result = self.gql(
  File "/home/uosai/Desktop/miniconda3/envs/marl/lib/python3.9/site-packages/wandb/sdk/internal/internal_api.py", line 341, in gql
    ret = self._retry_gql(
  File "/home/uosai/Desktop/miniconda3/envs/marl/lib/python3.9/site-packages/wandb/sdk/lib/retry.py", line 147, in __call__
    retry_timedelta_triggered = check_retry_fn(e)
  File "/home/uosai/Desktop/miniconda3/envs/marl/lib/python3.9/site-packages/wandb/util.py", line 907, in no_retry_auth
    raise CommError(
wandb.errors.CommError: It appears that you do not have permission to access the requested resource. Please reach out to the project owner to grant you access. If you have the correct permissions, verify that there are no issues with your networking setup.(Error 404: Not Found)
2024-05-29 17:34:05,554 ERROR   wandb-upload_3:371541 [internal_api.py:execute():373] 404 response executing GraphQL.
2024-05-29 17:34:05,555 ERROR   wandb-upload_3:371541 [internal_api.py:execute():374] {"errors":[{"message":"run StarCraft2_3m/yno7tz4a not found during createRunFiles","path":["createRunFiles"]}],"data":{"createRunFiles":null}}
2024-05-29 17:34:05,555 ERROR   Thread-11 :371541 [step_upload.py:_handle_event():200] Failed to upload file: /home/uosai/Desktop/on-policy/onpolicy/scripts/results/StarCraft2/3m/rmappo/Original_Mappo/wandb/run-20240529_173322-yno7tz4a/files/critic.pt
Traceback (most recent call last):
  File "/home/uosai/Desktop/miniconda3/envs/marl/lib/python3.9/site-packages/wandb/sdk/lib/retry.py", line 131, in __call__
    result = self._call_fn(*args, **kwargs)
  File "/home/uosai/Desktop/miniconda3/envs/marl/lib/python3.9/site-packages/wandb/sdk/internal/internal_api.py", line 369, in execute
    return self.client.execute(*args, **kwargs)  # type: ignore
  File "/home/uosai/Desktop/miniconda3/envs/marl/lib/python3.9/site-packages/wandb/vendor/gql-0.2.0/wandb_gql/client.py", line 52, in execute
    result = self._get_result(document, *args, **kwargs)
  File "/home/uosai/Desktop/miniconda3/envs/marl/lib/python3.9/site-packages/wandb/vendor/gql-0.2.0/wandb_gql/client.py", line 60, in _get_result
    return self.transport.execute(document, *args, **kwargs)
  File "/home/uosai/Desktop/miniconda3/envs/marl/lib/python3.9/site-packages/wandb/sdk/lib/gql_request.py", line 59, in execute
    request.raise_for_status()
  File "/home/uosai/Desktop/miniconda3/envs/marl/lib/python3.9/site-packages/requests/models.py", line 1021, in raise_for_status
    raise HTTPError(http_error_msg, response=self)
requests.exceptions.HTTPError: 404 Client Error: Not Found for url: https://api.wandb.ai/graphql

During handling of the above exception, another exception occurred:

Traceback (most recent call last):
  File "/home/uosai/Desktop/miniconda3/envs/marl/lib/python3.9/concurrent/futures/thread.py", line 58, in run
    result = self.fn(*self.args, **self.kwargs)
  File "/home/uosai/Desktop/miniconda3/envs/marl/lib/python3.9/site-packages/wandb/filesync/step_upload.py", line 288, in run_and_notify
    self._do_upload_sync(event)
  File "/home/uosai/Desktop/miniconda3/envs/marl/lib/python3.9/site-packages/wandb/filesync/step_upload.py", line 330, in _do_upload_sync
    job.run()
  File "/home/uosai/Desktop/miniconda3/envs/marl/lib/python3.9/site-packages/wandb/filesync/upload_job.py", line 57, in run
    self.push()
  File "/home/uosai/Desktop/miniconda3/envs/marl/lib/python3.9/site-packages/wandb/filesync/upload_job.py", line 106, in push
    _, upload_headers, result = self._api.upload_urls(project, [self.save_name])
  File "/home/uosai/Desktop/miniconda3/envs/marl/lib/python3.9/site-packages/wandb/apis/normalize.py", line 73, in wrapper
    raise err
  File "/home/uosai/Desktop/miniconda3/envs/marl/lib/python3.9/site-packages/wandb/apis/normalize.py", line 41, in wrapper
    return func(*args, **kwargs)
  File "/home/uosai/Desktop/miniconda3/envs/marl/lib/python3.9/site-packages/wandb/sdk/internal/internal_api.py", line 2384, in upload_urls
    query_result = self.gql(
  File "/home/uosai/Desktop/miniconda3/envs/marl/lib/python3.9/site-packages/wandb/sdk/internal/internal_api.py", line 341, in gql
    ret = self._retry_gql(
  File "/home/uosai/Desktop/miniconda3/envs/marl/lib/python3.9/site-packages/wandb/sdk/lib/retry.py", line 147, in __call__
    retry_timedelta_triggered = check_retry_fn(e)
  File "/home/uosai/Desktop/miniconda3/envs/marl/lib/python3.9/site-packages/wandb/util.py", line 907, in no_retry_auth
    raise CommError(
wandb.errors.CommError: It appears that you do not have permission to access the requested resource. Please reach out to the project owner to grant you access. If you have the correct permissions, verify that there are no issues with your networking setup.(Error 404: Not Found)
2024-05-29 17:34:05,561 ERROR   wandb-upload_2:371541 [internal_api.py:execute():373] 404 response executing GraphQL.
2024-05-29 17:34:05,562 ERROR   wandb-upload_2:371541 [internal_api.py:execute():374] {"errors":[{"message":"run StarCraft2_3m/yno7tz4a not found during createRunFiles","path":["createRunFiles"]}],"data":{"createRunFiles":null}}
2024-05-29 17:34:05,562 ERROR   Thread-11 :371541 [step_upload.py:_handle_event():200] Failed to upload file: /home/uosai/Desktop/on-policy/onpolicy/scripts/results/StarCraft2/3m/rmappo/Original_Mappo/wandb/run-20240529_173322-yno7tz4a/files/requirements.txt
Traceback (most recent call last):
  File "/home/uosai/Desktop/miniconda3/envs/marl/lib/python3.9/site-packages/wandb/sdk/lib/retry.py", line 131, in __call__
    result = self._call_fn(*args, **kwargs)
  File "/home/uosai/Desktop/miniconda3/envs/marl/lib/python3.9/site-packages/wandb/sdk/internal/internal_api.py", line 369, in execute
    return self.client.execute(*args, **kwargs)  # type: ignore
  File "/home/uosai/Desktop/miniconda3/envs/marl/lib/python3.9/site-packages/wandb/vendor/gql-0.2.0/wandb_gql/client.py", line 52, in execute
    result = self._get_result(document, *args, **kwargs)
  File "/home/uosai/Desktop/miniconda3/envs/marl/lib/python3.9/site-packages/wandb/vendor/gql-0.2.0/wandb_gql/client.py", line 60, in _get_result
    return self.transport.execute(document, *args, **kwargs)
  File "/home/uosai/Desktop/miniconda3/envs/marl/lib/python3.9/site-packages/wandb/sdk/lib/gql_request.py", line 59, in execute
    request.raise_for_status()
  File "/home/uosai/Desktop/miniconda3/envs/marl/lib/python3.9/site-packages/requests/models.py", line 1021, in raise_for_status
    raise HTTPError(http_error_msg, response=self)
requests.exceptions.HTTPError: 404 Client Error: Not Found for url: https://api.wandb.ai/graphql

During handling of the above exception, another exception occurred:

Traceback (most recent call last):
  File "/home/uosai/Desktop/miniconda3/envs/marl/lib/python3.9/concurrent/futures/thread.py", line 58, in run
    result = self.fn(*self.args, **self.kwargs)
  File "/home/uosai/Desktop/miniconda3/envs/marl/lib/python3.9/site-packages/wandb/filesync/step_upload.py", line 288, in run_and_notify
    self._do_upload_sync(event)
  File "/home/uosai/Desktop/miniconda3/envs/marl/lib/python3.9/site-packages/wandb/filesync/step_upload.py", line 330, in _do_upload_sync
    job.run()
  File "/home/uosai/Desktop/miniconda3/envs/marl/lib/python3.9/site-packages/wandb/filesync/upload_job.py", line 57, in run
    self.push()
  File "/home/uosai/Desktop/miniconda3/envs/marl/lib/python3.9/site-packages/wandb/filesync/upload_job.py", line 106, in push
    _, upload_headers, result = self._api.upload_urls(project, [self.save_name])
  File "/home/uosai/Desktop/miniconda3/envs/marl/lib/python3.9/site-packages/wandb/apis/normalize.py", line 73, in wrapper
    raise err
  File "/home/uosai/Desktop/miniconda3/envs/marl/lib/python3.9/site-packages/wandb/apis/normalize.py", line 41, in wrapper
    return func(*args, **kwargs)
  File "/home/uosai/Desktop/miniconda3/envs/marl/lib/python3.9/site-packages/wandb/sdk/internal/internal_api.py", line 2384, in upload_urls
    query_result = self.gql(
  File "/home/uosai/Desktop/miniconda3/envs/marl/lib/python3.9/site-packages/wandb/sdk/internal/internal_api.py", line 341, in gql
    ret = self._retry_gql(
  File "/home/uosai/Desktop/miniconda3/envs/marl/lib/python3.9/site-packages/wandb/sdk/lib/retry.py", line 147, in __call__
    retry_timedelta_triggered = check_retry_fn(e)
  File "/home/uosai/Desktop/miniconda3/envs/marl/lib/python3.9/site-packages/wandb/util.py", line 907, in no_retry_auth
    raise CommError(
wandb.errors.CommError: It appears that you do not have permission to access the requested resource. Please reach out to the project owner to grant you access. If you have the correct permissions, verify that there are no issues with your networking setup.(Error 404: Not Found)
2024-05-29 17:34:05,565 ERROR   wandb-upload_5:371541 [internal_api.py:execute():373] 404 response executing GraphQL.
2024-05-29 17:34:05,565 ERROR   wandb-upload_5:371541 [internal_api.py:execute():374] {"errors":[{"message":"run StarCraft2_3m/yno7tz4a not found during createRunFiles","path":["createRunFiles"]}],"data":{"createRunFiles":null}}
2024-05-29 17:34:05,566 INFO    MainThread:371541 [internal.py:handle_exit():76] Internal process exited
2024-05-29 17:34:05,566 ERROR   Thread-11 :371541 [step_upload.py:_handle_event():200] Failed to upload file: /home/uosai/Desktop/on-policy/onpolicy/scripts/results/StarCraft2/3m/rmappo/Original_Mappo/wandb/run-20240529_173322-yno7tz4a/files/output.log
Traceback (most recent call last):
  File "/home/uosai/Desktop/miniconda3/envs/marl/lib/python3.9/site-packages/wandb/sdk/lib/retry.py", line 131, in __call__
    result = self._call_fn(*args, **kwargs)
  File "/home/uosai/Desktop/miniconda3/envs/marl/lib/python3.9/site-packages/wandb/sdk/internal/internal_api.py", line 369, in execute
    return self.client.execute(*args, **kwargs)  # type: ignore
  File "/home/uosai/Desktop/miniconda3/envs/marl/lib/python3.9/site-packages/wandb/vendor/gql-0.2.0/wandb_gql/client.py", line 52, in execute
    result = self._get_result(document, *args, **kwargs)
  File "/home/uosai/Desktop/miniconda3/envs/marl/lib/python3.9/site-packages/wandb/vendor/gql-0.2.0/wandb_gql/client.py", line 60, in _get_result
    return self.transport.execute(document, *args, **kwargs)
  File "/home/uosai/Desktop/miniconda3/envs/marl/lib/python3.9/site-packages/wandb/sdk/lib/gql_request.py", line 59, in execute
    request.raise_for_status()
  File "/home/uosai/Desktop/miniconda3/envs/marl/lib/python3.9/site-packages/requests/models.py", line 1021, in raise_for_status
    raise HTTPError(http_error_msg, response=self)
requests.exceptions.HTTPError: 404 Client Error: Not Found for url: https://api.wandb.ai/graphql

During handling of the above exception, another exception occurred:

Traceback (most recent call last):
  File "/home/uosai/Desktop/miniconda3/envs/marl/lib/python3.9/concurrent/futures/thread.py", line 58, in run
    result = self.fn(*self.args, **self.kwargs)
  File "/home/uosai/Desktop/miniconda3/envs/marl/lib/python3.9/site-packages/wandb/filesync/step_upload.py", line 288, in run_and_notify
    self._do_upload_sync(event)
  File "/home/uosai/Desktop/miniconda3/envs/marl/lib/python3.9/site-packages/wandb/filesync/step_upload.py", line 330, in _do_upload_sync
    job.run()
  File "/home/uosai/Desktop/miniconda3/envs/marl/lib/python3.9/site-packages/wandb/filesync/upload_job.py", line 57, in run
    self.push()
  File "/home/uosai/Desktop/miniconda3/envs/marl/lib/python3.9/site-packages/wandb/filesync/upload_job.py", line 106, in push
    _, upload_headers, result = self._api.upload_urls(project, [self.save_name])
  File "/home/uosai/Desktop/miniconda3/envs/marl/lib/python3.9/site-packages/wandb/apis/normalize.py", line 73, in wrapper
    raise err
  File "/home/uosai/Desktop/miniconda3/envs/marl/lib/python3.9/site-packages/wandb/apis/normalize.py", line 41, in wrapper
    return func(*args, **kwargs)
  File "/home/uosai/Desktop/miniconda3/envs/marl/lib/python3.9/site-packages/wandb/sdk/internal/internal_api.py", line 2384, in upload_urls
    query_result = self.gql(
  File "/home/uosai/Desktop/miniconda3/envs/marl/lib/python3.9/site-packages/wandb/sdk/internal/internal_api.py", line 341, in gql
    ret = self._retry_gql(
  File "/home/uosai/Desktop/miniconda3/envs/marl/lib/python3.9/site-packages/wandb/sdk/lib/retry.py", line 147, in __call__
    retry_timedelta_triggered = check_retry_fn(e)
  File "/home/uosai/Desktop/miniconda3/envs/marl/lib/python3.9/site-packages/wandb/util.py", line 907, in no_retry_auth
    raise CommError(
wandb.errors.CommError: It appears that you do not have permission to access the requested resource. Please reach out to the project owner to grant you access. If you have the correct permissions, verify that there are no issues with your networking setup.(Error 404: Not Found)
