2024-05-31 21:18:12,596 INFO    StreamThr :1510841 [internal.py:wandb_internal():86] W&B internal server running at pid: 1510841, started at: 2024-05-31 21:18:12.595712
2024-05-31 21:18:12,597 DEBUG   HandlerThread:1510841 [handler.py:handle_request():146] handle_request: status
2024-05-31 21:18:12,600 INFO    WriterThread:1510841 [datastore.py:open_for_write():87] open: /home/uosai/Desktop/on-policy/onpolicy/scripts/results/StarCraft2/3m/rmappo/MAPPO/wandb/run-20240531_211812-cgmjqjo6/run-cgmjqjo6.wandb
2024-05-31 21:18:12,600 DEBUG   SenderThread:1510841 [sender.py:send():382] send: header
2024-05-31 21:18:12,616 DEBUG   SenderThread:1510841 [sender.py:send():382] send: run
2024-05-31 21:18:13,152 INFO    SenderThread:1510841 [dir_watcher.py:__init__():211] watching files in: /home/uosai/Desktop/on-policy/onpolicy/scripts/results/StarCraft2/3m/rmappo/MAPPO/wandb/run-20240531_211812-cgmjqjo6/files
2024-05-31 21:18:13,153 INFO    SenderThread:1510841 [sender.py:_start_run_threads():1136] run started: cgmjqjo6 with start time 1717157892.595452
2024-05-31 21:18:13,163 DEBUG   HandlerThread:1510841 [handler.py:handle_request():146] handle_request: check_version
2024-05-31 21:18:13,163 DEBUG   SenderThread:1510841 [sender.py:send_request():409] send_request: check_version
2024-05-31 21:18:13,272 DEBUG   HandlerThread:1510841 [handler.py:handle_request():146] handle_request: run_start
2024-05-31 21:18:13,282 DEBUG   HandlerThread:1510841 [system_info.py:__init__():27] System info init
2024-05-31 21:18:13,282 DEBUG   HandlerThread:1510841 [system_info.py:__init__():42] System info init done
2024-05-31 21:18:13,282 INFO    HandlerThread:1510841 [system_monitor.py:start():194] Starting system monitor
2024-05-31 21:18:13,282 INFO    SystemMonitor:1510841 [system_monitor.py:_start():158] Starting system asset monitoring threads
2024-05-31 21:18:13,282 INFO    HandlerThread:1510841 [system_monitor.py:probe():214] Collecting system info
2024-05-31 21:18:13,282 INFO    SystemMonitor:1510841 [interfaces.py:start():190] Started cpu monitoring
2024-05-31 21:18:13,283 INFO    SystemMonitor:1510841 [interfaces.py:start():190] Started disk monitoring
2024-05-31 21:18:13,283 INFO    SystemMonitor:1510841 [interfaces.py:start():190] Started gpu monitoring
2024-05-31 21:18:13,284 INFO    SystemMonitor:1510841 [interfaces.py:start():190] Started memory monitoring
2024-05-31 21:18:13,285 INFO    SystemMonitor:1510841 [interfaces.py:start():190] Started network monitoring
2024-05-31 21:18:13,297 DEBUG   HandlerThread:1510841 [system_info.py:probe():151] Probing system
2024-05-31 21:18:13,305 DEBUG   HandlerThread:1510841 [system_info.py:_probe_git():136] Probing git
2024-05-31 21:18:13,321 DEBUG   HandlerThread:1510841 [system_info.py:_probe_git():144] Probing git done
2024-05-31 21:18:13,321 DEBUG   HandlerThread:1510841 [system_info.py:probe():199] Probing system done
2024-05-31 21:18:13,321 DEBUG   HandlerThread:1510841 [system_monitor.py:probe():223] {'os': 'Linux-6.5.0-35-generic-x86_64-with-glibc2.35', 'python': '3.9.18', 'heartbeatAt': '2024-05-31T12:18:13.297757', 'startedAt': '2024-05-31T12:18:12.590354', 'docker': None, 'cuda': None, 'args': ('--seed', '234', '--env_name', 'StarCraft2', '--experiment_name', 'MAPPO', '--group_name', 'sampling_cluster20_MAPPO', '--num_clusters', '20', '--use_pre_sampling', '--num_pre_sampling', '1', '--num_gpu', '1'), 'state': 'running', 'program': '/home/uosai/Desktop/on-policy/onpolicy/scripts/train/train_smac.py', 'codePathLocal': 'train_smac.py', 'codePath': 'onpolicy/scripts/train/train_smac.py', 'git': {'remote': 'https://github.com/singforai/on-policy.git', 'commit': '14d4b373e79555e79221655c211e9561875c023b'}, 'email': 'singfor7012@gmail.com', 'root': '/home/uosai/Desktop/on-policy', 'host': 'uos-desktop', 'username': 'uosai', 'executable': '/home/uosai/Desktop/miniconda3/envs/marl/bin/python', 'cpu_count': 12, 'cpu_count_logical': 24, 'cpu_freq': {'current': 4449.427708333334, 'min': 2200.0, 'max': 3700.0}, 'cpu_freq_per_core': [{'current': 4416.668, 'min': 2200.0, 'max': 3700.0}, {'current': 4416.231, 'min': 2200.0, 'max': 3700.0}, {'current': 3542.094, 'min': 2200.0, 'max': 3700.0}, {'current': 4416.64, 'min': 2200.0, 'max': 3700.0}, {'current': 4414.804, 'min': 2200.0, 'max': 3700.0}, {'current': 4418.647, 'min': 2200.0, 'max': 3700.0}, {'current': 4416.634, 'min': 2200.0, 'max': 3700.0}, {'current': 4416.614, 'min': 2200.0, 'max': 3700.0}, {'current': 4416.663, 'min': 2200.0, 'max': 3700.0}, {'current': 4416.652, 'min': 2200.0, 'max': 3700.0}, {'current': 3579.1, 'min': 2200.0, 'max': 3700.0}, {'current': 4416.656, 'min': 2200.0, 'max': 3700.0}, {'current': 4417.213, 'min': 2200.0, 'max': 3700.0}, {'current': 4416.658, 'min': 2200.0, 'max': 3700.0}, {'current': 4421.544, 'min': 2200.0, 'max': 3700.0}, {'current': 4419.8, 'min': 2200.0, 'max': 3700.0}, {'current': 4416.661, 'min': 2200.0, 'max': 3700.0}, {'current': 4416.659, 'min': 2200.0, 'max': 3700.0}, {'current': 4415.512, 'min': 2200.0, 'max': 3700.0}, {'current': 4416.661, 'min': 2200.0, 'max': 3700.0}, {'current': 4417.342, 'min': 2200.0, 'max': 3700.0}, {'current': 4417.625, 'min': 2200.0, 'max': 3700.0}, {'current': 4433.736, 'min': 2200.0, 'max': 3700.0}, {'current': 4419.621, 'min': 2200.0, 'max': 3700.0}], 'disk': {'/': {'total': 233.17998886108398, 'used': 193.23759841918945}}, 'gpu': 'NVIDIA GeForce RTX 3080', 'gpu_count': 2, 'gpu_devices': [{'name': 'NVIDIA GeForce RTX 3080', 'memory_total': 10737418240}, {'name': 'NVIDIA GeForce RTX 3080', 'memory_total': 10737418240}], 'memory': {'total': 62.709049224853516}}
2024-05-31 21:18:13,321 INFO    HandlerThread:1510841 [system_monitor.py:probe():224] Finished collecting system info
2024-05-31 21:18:13,321 INFO    HandlerThread:1510841 [system_monitor.py:probe():227] Publishing system info
2024-05-31 21:18:13,321 DEBUG   HandlerThread:1510841 [system_info.py:_save_conda():208] Saving list of conda packages installed into the current environment
2024-05-31 21:18:14,155 INFO    Thread-12 :1510841 [dir_watcher.py:_on_file_created():271] file/dir created: /home/uosai/Desktop/on-policy/onpolicy/scripts/results/StarCraft2/3m/rmappo/MAPPO/wandb/run-20240531_211812-cgmjqjo6/files/conda-environment.yaml
2024-05-31 21:18:14,976 DEBUG   HandlerThread:1510841 [system_info.py:_save_conda():220] Saving conda packages done
2024-05-31 21:18:14,977 INFO    HandlerThread:1510841 [system_monitor.py:probe():229] Finished publishing system info
2024-05-31 21:18:14,979 DEBUG   SenderThread:1510841 [sender.py:send():382] send: files
2024-05-31 21:18:14,979 INFO    SenderThread:1510841 [sender.py:_save_file():1403] saving file wandb-metadata.json with policy now
2024-05-31 21:18:14,983 DEBUG   HandlerThread:1510841 [handler.py:handle_request():146] handle_request: python_packages
2024-05-31 21:18:14,983 DEBUG   SenderThread:1510841 [sender.py:send_request():409] send_request: python_packages
2024-05-31 21:18:14,985 DEBUG   HandlerThread:1510841 [handler.py:handle_request():146] handle_request: stop_status
2024-05-31 21:18:14,985 DEBUG   HandlerThread:1510841 [handler.py:handle_request():146] handle_request: internal_messages
2024-05-31 21:18:14,986 DEBUG   SenderThread:1510841 [sender.py:send_request():409] send_request: stop_status
2024-05-31 21:18:15,153 INFO    Thread-12 :1510841 [dir_watcher.py:_on_file_modified():288] file/dir modified: /home/uosai/Desktop/on-policy/onpolicy/scripts/results/StarCraft2/3m/rmappo/MAPPO/wandb/run-20240531_211812-cgmjqjo6/files/conda-environment.yaml
2024-05-31 21:18:15,153 INFO    Thread-12 :1510841 [dir_watcher.py:_on_file_created():271] file/dir created: /home/uosai/Desktop/on-policy/onpolicy/scripts/results/StarCraft2/3m/rmappo/MAPPO/wandb/run-20240531_211812-cgmjqjo6/files/wandb-metadata.json
2024-05-31 21:18:15,154 INFO    Thread-12 :1510841 [dir_watcher.py:_on_file_created():271] file/dir created: /home/uosai/Desktop/on-policy/onpolicy/scripts/results/StarCraft2/3m/rmappo/MAPPO/wandb/run-20240531_211812-cgmjqjo6/files/requirements.txt
2024-05-31 21:18:15,275 DEBUG   SenderThread:1510841 [sender.py:send():382] send: telemetry
2024-05-31 21:18:15,749 INFO    wandb-upload_0:1510841 [upload_job.py:push():131] Uploaded file /tmp/tmpdwqp3tcowandb/lwhss5v2-wandb-metadata.json
2024-05-31 21:18:18,276 DEBUG   HandlerThread:1510841 [handler.py:handle_request():146] handle_request: status_report
2024-05-31 21:18:21,155 INFO    Thread-12 :1510841 [dir_watcher.py:_on_file_created():271] file/dir created: /home/uosai/Desktop/on-policy/onpolicy/scripts/results/StarCraft2/3m/rmappo/MAPPO/wandb/run-20240531_211812-cgmjqjo6/files/output.log
2024-05-31 21:18:22,852 DEBUG   HandlerThread:1510841 [handler.py:handle_request():146] handle_request: partial_history
2024-05-31 21:18:22,852 DEBUG   HandlerThread:1510841 [handler.py:handle_request():146] handle_request: partial_history
2024-05-31 21:18:22,853 DEBUG   HandlerThread:1510841 [handler.py:handle_request():146] handle_request: partial_history
2024-05-31 21:18:22,853 DEBUG   HandlerThread:1510841 [handler.py:handle_request():146] handle_request: partial_history
2024-05-31 21:18:23,101 DEBUG   HandlerThread:1510841 [handler.py:handle_request():146] handle_request: partial_history
2024-05-31 21:18:23,101 DEBUG   HandlerThread:1510841 [handler.py:handle_request():146] handle_request: partial_history
2024-05-31 21:18:23,101 DEBUG   HandlerThread:1510841 [handler.py:handle_request():146] handle_request: partial_history
2024-05-31 21:18:23,101 DEBUG   HandlerThread:1510841 [handler.py:handle_request():146] handle_request: partial_history
2024-05-31 21:18:23,102 DEBUG   HandlerThread:1510841 [handler.py:handle_request():146] handle_request: partial_history
2024-05-31 21:18:23,155 INFO    Thread-12 :1510841 [dir_watcher.py:_on_file_modified():288] file/dir modified: /home/uosai/Desktop/on-policy/onpolicy/scripts/results/StarCraft2/3m/rmappo/MAPPO/wandb/run-20240531_211812-cgmjqjo6/files/output.log
2024-05-31 21:18:23,156 INFO    Thread-12 :1510841 [dir_watcher.py:_on_file_created():271] file/dir created: /home/uosai/Desktop/on-policy/onpolicy/scripts/results/StarCraft2/3m/rmappo/MAPPO/wandb/run-20240531_211812-cgmjqjo6/files/critic.pt
2024-05-31 21:18:23,156 INFO    Thread-12 :1510841 [dir_watcher.py:_on_file_created():271] file/dir created: /home/uosai/Desktop/on-policy/onpolicy/scripts/results/StarCraft2/3m/rmappo/MAPPO/wandb/run-20240531_211812-cgmjqjo6/files/actor.pt
2024-05-31 21:18:24,102 DEBUG   HandlerThread:1510841 [handler.py:handle_request():146] handle_request: status_report
2024-05-31 21:18:24,716 ERROR   FileStreamThread:1510841 [file_stream.py:_handle_response():504] dropped chunk 404 Client Error: Not Found for url: https://api.wandb.ai/files/singfor7012/StarCraft2_3m/cgmjqjo6/file_stream
NoneType: None
2024-05-31 21:18:25,156 INFO    Thread-12 :1510841 [dir_watcher.py:_on_file_modified():288] file/dir modified: /home/uosai/Desktop/on-policy/onpolicy/scripts/results/StarCraft2/3m/rmappo/MAPPO/wandb/run-20240531_211812-cgmjqjo6/files/output.log
2024-05-31 21:18:27,060 ERROR   FileStreamThread:1510841 [file_stream.py:_handle_response():504] dropped chunk 404 Client Error: Not Found for url: https://api.wandb.ai/files/singfor7012/StarCraft2_3m/cgmjqjo6/file_stream
NoneType: None
2024-05-31 21:18:28,157 DEBUG   HandlerThread:1510841 [handler.py:handle_request():146] handle_request: partial_history
2024-05-31 21:18:28,158 DEBUG   HandlerThread:1510841 [handler.py:handle_request():146] handle_request: partial_history
2024-05-31 21:18:29,061 ERROR   FileStreamThread:1510841 [file_stream.py:_handle_response():504] dropped chunk 404 Client Error: Not Found for url: https://api.wandb.ai/files/singfor7012/StarCraft2_3m/cgmjqjo6/file_stream
NoneType: None
2024-05-31 21:18:29,158 INFO    Thread-12 :1510841 [dir_watcher.py:_on_file_modified():288] file/dir modified: /home/uosai/Desktop/on-policy/onpolicy/scripts/results/StarCraft2/3m/rmappo/MAPPO/wandb/run-20240531_211812-cgmjqjo6/files/output.log
2024-05-31 21:18:29,159 DEBUG   HandlerThread:1510841 [handler.py:handle_request():146] handle_request: status_report
2024-05-31 21:18:29,613 WARNING StreamThr :1510841 [internal.py:is_dead():414] Internal process exiting, parent pid 1510201 disappeared
2024-05-31 21:18:29,614 ERROR   StreamThr :1510841 [internal.py:wandb_internal():152] Internal process shutdown.
2024-05-31 21:18:30,159 INFO    SenderThread:1510841 [sender.py:finish():1572] shutting down sender
2024-05-31 21:18:30,159 INFO    WriterThread:1510841 [datastore.py:close():296] close: /home/uosai/Desktop/on-policy/onpolicy/scripts/results/StarCraft2/3m/rmappo/MAPPO/wandb/run-20240531_211812-cgmjqjo6/run-cgmjqjo6.wandb
2024-05-31 21:18:30,159 INFO    HandlerThread:1510841 [handler.py:finish():869] shutting down handler
2024-05-31 21:18:30,159 INFO    HandlerThread:1510841 [system_monitor.py:finish():203] Stopping system monitor
2024-05-31 21:18:30,160 DEBUG   SystemMonitor:1510841 [system_monitor.py:_start():172] Starting system metrics aggregation loop
2024-05-31 21:18:30,160 INFO    HandlerThread:1510841 [interfaces.py:finish():202] Joined cpu monitor
2024-05-31 21:18:30,160 DEBUG   SystemMonitor:1510841 [system_monitor.py:_start():179] Finished system metrics aggregation loop
2024-05-31 21:18:30,161 INFO    HandlerThread:1510841 [interfaces.py:finish():202] Joined disk monitor
2024-05-31 21:18:30,161 DEBUG   SystemMonitor:1510841 [system_monitor.py:_start():183] Publishing last batch of metrics
2024-05-31 21:18:30,162 INFO    HandlerThread:1510841 [interfaces.py:finish():202] Joined gpu monitor
2024-05-31 21:18:30,162 INFO    HandlerThread:1510841 [interfaces.py:finish():202] Joined memory monitor
2024-05-31 21:18:30,163 INFO    HandlerThread:1510841 [interfaces.py:finish():202] Joined network monitor
2024-05-31 21:18:30,862 INFO    SenderThread:1510841 [dir_watcher.py:finish():358] shutting down directory watcher
2024-05-31 21:18:31,159 INFO    SenderThread:1510841 [dir_watcher.py:_on_file_modified():288] file/dir modified: /home/uosai/Desktop/on-policy/onpolicy/scripts/results/StarCraft2/3m/rmappo/MAPPO/wandb/run-20240531_211812-cgmjqjo6/files/output.log
2024-05-31 21:18:31,159 INFO    SenderThread:1510841 [dir_watcher.py:finish():388] scan: /home/uosai/Desktop/on-policy/onpolicy/scripts/results/StarCraft2/3m/rmappo/MAPPO/wandb/run-20240531_211812-cgmjqjo6/files
2024-05-31 21:18:31,159 INFO    SenderThread:1510841 [dir_watcher.py:finish():402] scan save: /home/uosai/Desktop/on-policy/onpolicy/scripts/results/StarCraft2/3m/rmappo/MAPPO/wandb/run-20240531_211812-cgmjqjo6/files/actor.pt actor.pt
2024-05-31 21:18:31,159 INFO    SenderThread:1510841 [dir_watcher.py:finish():402] scan save: /home/uosai/Desktop/on-policy/onpolicy/scripts/results/StarCraft2/3m/rmappo/MAPPO/wandb/run-20240531_211812-cgmjqjo6/files/conda-environment.yaml conda-environment.yaml
2024-05-31 21:18:31,161 INFO    SenderThread:1510841 [dir_watcher.py:finish():402] scan save: /home/uosai/Desktop/on-policy/onpolicy/scripts/results/StarCraft2/3m/rmappo/MAPPO/wandb/run-20240531_211812-cgmjqjo6/files/requirements.txt requirements.txt
2024-05-31 21:18:31,162 INFO    SenderThread:1510841 [dir_watcher.py:finish():402] scan save: /home/uosai/Desktop/on-policy/onpolicy/scripts/results/StarCraft2/3m/rmappo/MAPPO/wandb/run-20240531_211812-cgmjqjo6/files/critic.pt critic.pt
2024-05-31 21:18:31,164 INFO    SenderThread:1510841 [dir_watcher.py:finish():402] scan save: /home/uosai/Desktop/on-policy/onpolicy/scripts/results/StarCraft2/3m/rmappo/MAPPO/wandb/run-20240531_211812-cgmjqjo6/files/config.yaml config.yaml
2024-05-31 21:18:31,165 INFO    SenderThread:1510841 [dir_watcher.py:finish():402] scan save: /home/uosai/Desktop/on-policy/onpolicy/scripts/results/StarCraft2/3m/rmappo/MAPPO/wandb/run-20240531_211812-cgmjqjo6/files/wandb-metadata.json wandb-metadata.json
2024-05-31 21:18:31,167 INFO    SenderThread:1510841 [dir_watcher.py:finish():402] scan save: /home/uosai/Desktop/on-policy/onpolicy/scripts/results/StarCraft2/3m/rmappo/MAPPO/wandb/run-20240531_211812-cgmjqjo6/files/output.log output.log
2024-05-31 21:18:31,167 INFO    SenderThread:1510841 [file_pusher.py:finish():175] shutting down file pusher
2024-05-31 21:18:31,168 INFO    SenderThread:1510841 [file_pusher.py:join():181] waiting for file pusher
2024-05-31 21:18:31,349 ERROR   wandb-upload_0:1510841 [internal_api.py:execute():373] 404 response executing GraphQL.
2024-05-31 21:18:31,349 ERROR   wandb-upload_0:1510841 [internal_api.py:execute():374] {"errors":[{"message":"run StarCraft2_3m/cgmjqjo6 not found during createRunFiles","path":["createRunFiles"]}],"data":{"createRunFiles":null}}
2024-05-31 21:18:31,350 ERROR   Thread-11 :1510841 [step_upload.py:_handle_event():200] Failed to upload file: /home/uosai/Desktop/on-policy/onpolicy/scripts/results/StarCraft2/3m/rmappo/MAPPO/wandb/run-20240531_211812-cgmjqjo6/files/actor.pt
Traceback (most recent call last):
  File "/home/uosai/Desktop/miniconda3/envs/marl/lib/python3.9/site-packages/wandb/sdk/lib/retry.py", line 131, in __call__
    result = self._call_fn(*args, **kwargs)
  File "/home/uosai/Desktop/miniconda3/envs/marl/lib/python3.9/site-packages/wandb/sdk/internal/internal_api.py", line 369, in execute
    return self.client.execute(*args, **kwargs)  # type: ignore
  File "/home/uosai/Desktop/miniconda3/envs/marl/lib/python3.9/site-packages/wandb/vendor/gql-0.2.0/wandb_gql/client.py", line 52, in execute
    result = self._get_result(document, *args, **kwargs)
  File "/home/uosai/Desktop/miniconda3/envs/marl/lib/python3.9/site-packages/wandb/vendor/gql-0.2.0/wandb_gql/client.py", line 60, in _get_result
    return self.transport.execute(document, *args, **kwargs)
  File "/home/uosai/Desktop/miniconda3/envs/marl/lib/python3.9/site-packages/wandb/sdk/lib/gql_request.py", line 59, in execute
    request.raise_for_status()
  File "/home/uosai/Desktop/miniconda3/envs/marl/lib/python3.9/site-packages/requests/models.py", line 1021, in raise_for_status
    raise HTTPError(http_error_msg, response=self)
requests.exceptions.HTTPError: 404 Client Error: Not Found for url: https://api.wandb.ai/graphql

During handling of the above exception, another exception occurred:

Traceback (most recent call last):
  File "/home/uosai/Desktop/miniconda3/envs/marl/lib/python3.9/concurrent/futures/thread.py", line 58, in run
    result = self.fn(*self.args, **self.kwargs)
  File "/home/uosai/Desktop/miniconda3/envs/marl/lib/python3.9/site-packages/wandb/filesync/step_upload.py", line 288, in run_and_notify
    self._do_upload_sync(event)
  File "/home/uosai/Desktop/miniconda3/envs/marl/lib/python3.9/site-packages/wandb/filesync/step_upload.py", line 330, in _do_upload_sync
    job.run()
  File "/home/uosai/Desktop/miniconda3/envs/marl/lib/python3.9/site-packages/wandb/filesync/upload_job.py", line 57, in run
    self.push()
  File "/home/uosai/Desktop/miniconda3/envs/marl/lib/python3.9/site-packages/wandb/filesync/upload_job.py", line 106, in push
    _, upload_headers, result = self._api.upload_urls(project, [self.save_name])
  File "/home/uosai/Desktop/miniconda3/envs/marl/lib/python3.9/site-packages/wandb/apis/normalize.py", line 73, in wrapper
    raise err
  File "/home/uosai/Desktop/miniconda3/envs/marl/lib/python3.9/site-packages/wandb/apis/normalize.py", line 41, in wrapper
    return func(*args, **kwargs)
  File "/home/uosai/Desktop/miniconda3/envs/marl/lib/python3.9/site-packages/wandb/sdk/internal/internal_api.py", line 2384, in upload_urls
    query_result = self.gql(
  File "/home/uosai/Desktop/miniconda3/envs/marl/lib/python3.9/site-packages/wandb/sdk/internal/internal_api.py", line 341, in gql
    ret = self._retry_gql(
  File "/home/uosai/Desktop/miniconda3/envs/marl/lib/python3.9/site-packages/wandb/sdk/lib/retry.py", line 147, in __call__
    retry_timedelta_triggered = check_retry_fn(e)
  File "/home/uosai/Desktop/miniconda3/envs/marl/lib/python3.9/site-packages/wandb/util.py", line 907, in no_retry_auth
    raise CommError(
wandb.errors.CommError: It appears that you do not have permission to access the requested resource. Please reach out to the project owner to grant you access. If you have the correct permissions, verify that there are no issues with your networking setup.(Error 404: Not Found)
2024-05-31 21:18:31,357 ERROR   wandb-upload_1:1510841 [internal_api.py:execute():373] 404 response executing GraphQL.
2024-05-31 21:18:31,357 ERROR   wandb-upload_1:1510841 [internal_api.py:execute():374] {"errors":[{"message":"run StarCraft2_3m/cgmjqjo6 not found during createRunFiles","path":["createRunFiles"]}],"data":{"createRunFiles":null}}
2024-05-31 21:18:31,358 ERROR   Thread-11 :1510841 [step_upload.py:_handle_event():200] Failed to upload file: /home/uosai/Desktop/on-policy/onpolicy/scripts/results/StarCraft2/3m/rmappo/MAPPO/wandb/run-20240531_211812-cgmjqjo6/files/conda-environment.yaml
Traceback (most recent call last):
  File "/home/uosai/Desktop/miniconda3/envs/marl/lib/python3.9/site-packages/wandb/sdk/lib/retry.py", line 131, in __call__
    result = self._call_fn(*args, **kwargs)
  File "/home/uosai/Desktop/miniconda3/envs/marl/lib/python3.9/site-packages/wandb/sdk/internal/internal_api.py", line 369, in execute
    return self.client.execute(*args, **kwargs)  # type: ignore
  File "/home/uosai/Desktop/miniconda3/envs/marl/lib/python3.9/site-packages/wandb/vendor/gql-0.2.0/wandb_gql/client.py", line 52, in execute
    result = self._get_result(document, *args, **kwargs)
  File "/home/uosai/Desktop/miniconda3/envs/marl/lib/python3.9/site-packages/wandb/vendor/gql-0.2.0/wandb_gql/client.py", line 60, in _get_result
    return self.transport.execute(document, *args, **kwargs)
  File "/home/uosai/Desktop/miniconda3/envs/marl/lib/python3.9/site-packages/wandb/sdk/lib/gql_request.py", line 59, in execute
    request.raise_for_status()
  File "/home/uosai/Desktop/miniconda3/envs/marl/lib/python3.9/site-packages/requests/models.py", line 1021, in raise_for_status
    raise HTTPError(http_error_msg, response=self)
requests.exceptions.HTTPError: 404 Client Error: Not Found for url: https://api.wandb.ai/graphql

During handling of the above exception, another exception occurred:

Traceback (most recent call last):
  File "/home/uosai/Desktop/miniconda3/envs/marl/lib/python3.9/concurrent/futures/thread.py", line 58, in run
    result = self.fn(*self.args, **self.kwargs)
  File "/home/uosai/Desktop/miniconda3/envs/marl/lib/python3.9/site-packages/wandb/filesync/step_upload.py", line 288, in run_and_notify
    self._do_upload_sync(event)
  File "/home/uosai/Desktop/miniconda3/envs/marl/lib/python3.9/site-packages/wandb/filesync/step_upload.py", line 330, in _do_upload_sync
    job.run()
  File "/home/uosai/Desktop/miniconda3/envs/marl/lib/python3.9/site-packages/wandb/filesync/upload_job.py", line 57, in run
    self.push()
  File "/home/uosai/Desktop/miniconda3/envs/marl/lib/python3.9/site-packages/wandb/filesync/upload_job.py", line 106, in push
    _, upload_headers, result = self._api.upload_urls(project, [self.save_name])
  File "/home/uosai/Desktop/miniconda3/envs/marl/lib/python3.9/site-packages/wandb/apis/normalize.py", line 73, in wrapper
    raise err
  File "/home/uosai/Desktop/miniconda3/envs/marl/lib/python3.9/site-packages/wandb/apis/normalize.py", line 41, in wrapper
    return func(*args, **kwargs)
  File "/home/uosai/Desktop/miniconda3/envs/marl/lib/python3.9/site-packages/wandb/sdk/internal/internal_api.py", line 2384, in upload_urls
    query_result = self.gql(
  File "/home/uosai/Desktop/miniconda3/envs/marl/lib/python3.9/site-packages/wandb/sdk/internal/internal_api.py", line 341, in gql
    ret = self._retry_gql(
  File "/home/uosai/Desktop/miniconda3/envs/marl/lib/python3.9/site-packages/wandb/sdk/lib/retry.py", line 147, in __call__
    retry_timedelta_triggered = check_retry_fn(e)
  File "/home/uosai/Desktop/miniconda3/envs/marl/lib/python3.9/site-packages/wandb/util.py", line 907, in no_retry_auth
    raise CommError(
wandb.errors.CommError: It appears that you do not have permission to access the requested resource. Please reach out to the project owner to grant you access. If you have the correct permissions, verify that there are no issues with your networking setup.(Error 404: Not Found)
2024-05-31 21:18:31,380 ERROR   wandb-upload_3:1510841 [internal_api.py:execute():373] 404 response executing GraphQL.
2024-05-31 21:18:31,380 ERROR   wandb-upload_3:1510841 [internal_api.py:execute():374] {"errors":[{"message":"run StarCraft2_3m/cgmjqjo6 not found during createRunFiles","path":["createRunFiles"]}],"data":{"createRunFiles":null}}
2024-05-31 21:18:31,380 ERROR   Thread-11 :1510841 [step_upload.py:_handle_event():200] Failed to upload file: /home/uosai/Desktop/on-policy/onpolicy/scripts/results/StarCraft2/3m/rmappo/MAPPO/wandb/run-20240531_211812-cgmjqjo6/files/critic.pt
Traceback (most recent call last):
  File "/home/uosai/Desktop/miniconda3/envs/marl/lib/python3.9/site-packages/wandb/sdk/lib/retry.py", line 131, in __call__
    result = self._call_fn(*args, **kwargs)
  File "/home/uosai/Desktop/miniconda3/envs/marl/lib/python3.9/site-packages/wandb/sdk/internal/internal_api.py", line 369, in execute
    return self.client.execute(*args, **kwargs)  # type: ignore
  File "/home/uosai/Desktop/miniconda3/envs/marl/lib/python3.9/site-packages/wandb/vendor/gql-0.2.0/wandb_gql/client.py", line 52, in execute
    result = self._get_result(document, *args, **kwargs)
  File "/home/uosai/Desktop/miniconda3/envs/marl/lib/python3.9/site-packages/wandb/vendor/gql-0.2.0/wandb_gql/client.py", line 60, in _get_result
    return self.transport.execute(document, *args, **kwargs)
  File "/home/uosai/Desktop/miniconda3/envs/marl/lib/python3.9/site-packages/wandb/sdk/lib/gql_request.py", line 59, in execute
    request.raise_for_status()
  File "/home/uosai/Desktop/miniconda3/envs/marl/lib/python3.9/site-packages/requests/models.py", line 1021, in raise_for_status
    raise HTTPError(http_error_msg, response=self)
requests.exceptions.HTTPError: 404 Client Error: Not Found for url: https://api.wandb.ai/graphql

During handling of the above exception, another exception occurred:

Traceback (most recent call last):
  File "/home/uosai/Desktop/miniconda3/envs/marl/lib/python3.9/concurrent/futures/thread.py", line 58, in run
    result = self.fn(*self.args, **self.kwargs)
  File "/home/uosai/Desktop/miniconda3/envs/marl/lib/python3.9/site-packages/wandb/filesync/step_upload.py", line 288, in run_and_notify
    self._do_upload_sync(event)
  File "/home/uosai/Desktop/miniconda3/envs/marl/lib/python3.9/site-packages/wandb/filesync/step_upload.py", line 330, in _do_upload_sync
    job.run()
  File "/home/uosai/Desktop/miniconda3/envs/marl/lib/python3.9/site-packages/wandb/filesync/upload_job.py", line 57, in run
    self.push()
  File "/home/uosai/Desktop/miniconda3/envs/marl/lib/python3.9/site-packages/wandb/filesync/upload_job.py", line 106, in push
    _, upload_headers, result = self._api.upload_urls(project, [self.save_name])
  File "/home/uosai/Desktop/miniconda3/envs/marl/lib/python3.9/site-packages/wandb/apis/normalize.py", line 73, in wrapper
    raise err
  File "/home/uosai/Desktop/miniconda3/envs/marl/lib/python3.9/site-packages/wandb/apis/normalize.py", line 41, in wrapper
    return func(*args, **kwargs)
  File "/home/uosai/Desktop/miniconda3/envs/marl/lib/python3.9/site-packages/wandb/sdk/internal/internal_api.py", line 2384, in upload_urls
    query_result = self.gql(
  File "/home/uosai/Desktop/miniconda3/envs/marl/lib/python3.9/site-packages/wandb/sdk/internal/internal_api.py", line 341, in gql
    ret = self._retry_gql(
  File "/home/uosai/Desktop/miniconda3/envs/marl/lib/python3.9/site-packages/wandb/sdk/lib/retry.py", line 147, in __call__
    retry_timedelta_triggered = check_retry_fn(e)
  File "/home/uosai/Desktop/miniconda3/envs/marl/lib/python3.9/site-packages/wandb/util.py", line 907, in no_retry_auth
    raise CommError(
wandb.errors.CommError: It appears that you do not have permission to access the requested resource. Please reach out to the project owner to grant you access. If you have the correct permissions, verify that there are no issues with your networking setup.(Error 404: Not Found)
2024-05-31 21:18:31,382 ERROR   wandb-upload_2:1510841 [internal_api.py:execute():373] 404 response executing GraphQL.
2024-05-31 21:18:31,382 ERROR   wandb-upload_2:1510841 [internal_api.py:execute():374] {"errors":[{"message":"run StarCraft2_3m/cgmjqjo6 not found during createRunFiles","path":["createRunFiles"]}],"data":{"createRunFiles":null}}
2024-05-31 21:18:31,382 ERROR   Thread-11 :1510841 [step_upload.py:_handle_event():200] Failed to upload file: /home/uosai/Desktop/on-policy/onpolicy/scripts/results/StarCraft2/3m/rmappo/MAPPO/wandb/run-20240531_211812-cgmjqjo6/files/requirements.txt
Traceback (most recent call last):
  File "/home/uosai/Desktop/miniconda3/envs/marl/lib/python3.9/site-packages/wandb/sdk/lib/retry.py", line 131, in __call__
    result = self._call_fn(*args, **kwargs)
  File "/home/uosai/Desktop/miniconda3/envs/marl/lib/python3.9/site-packages/wandb/sdk/internal/internal_api.py", line 369, in execute
    return self.client.execute(*args, **kwargs)  # type: ignore
  File "/home/uosai/Desktop/miniconda3/envs/marl/lib/python3.9/site-packages/wandb/vendor/gql-0.2.0/wandb_gql/client.py", line 52, in execute
    result = self._get_result(document, *args, **kwargs)
  File "/home/uosai/Desktop/miniconda3/envs/marl/lib/python3.9/site-packages/wandb/vendor/gql-0.2.0/wandb_gql/client.py", line 60, in _get_result
    return self.transport.execute(document, *args, **kwargs)
  File "/home/uosai/Desktop/miniconda3/envs/marl/lib/python3.9/site-packages/wandb/sdk/lib/gql_request.py", line 59, in execute
    request.raise_for_status()
  File "/home/uosai/Desktop/miniconda3/envs/marl/lib/python3.9/site-packages/requests/models.py", line 1021, in raise_for_status
    raise HTTPError(http_error_msg, response=self)
requests.exceptions.HTTPError: 404 Client Error: Not Found for url: https://api.wandb.ai/graphql

During handling of the above exception, another exception occurred:

Traceback (most recent call last):
  File "/home/uosai/Desktop/miniconda3/envs/marl/lib/python3.9/concurrent/futures/thread.py", line 58, in run
    result = self.fn(*self.args, **self.kwargs)
  File "/home/uosai/Desktop/miniconda3/envs/marl/lib/python3.9/site-packages/wandb/filesync/step_upload.py", line 288, in run_and_notify
    self._do_upload_sync(event)
  File "/home/uosai/Desktop/miniconda3/envs/marl/lib/python3.9/site-packages/wandb/filesync/step_upload.py", line 330, in _do_upload_sync
    job.run()
  File "/home/uosai/Desktop/miniconda3/envs/marl/lib/python3.9/site-packages/wandb/filesync/upload_job.py", line 57, in run
    self.push()
  File "/home/uosai/Desktop/miniconda3/envs/marl/lib/python3.9/site-packages/wandb/filesync/upload_job.py", line 106, in push
    _, upload_headers, result = self._api.upload_urls(project, [self.save_name])
  File "/home/uosai/Desktop/miniconda3/envs/marl/lib/python3.9/site-packages/wandb/apis/normalize.py", line 73, in wrapper
    raise err
  File "/home/uosai/Desktop/miniconda3/envs/marl/lib/python3.9/site-packages/wandb/apis/normalize.py", line 41, in wrapper
    return func(*args, **kwargs)
  File "/home/uosai/Desktop/miniconda3/envs/marl/lib/python3.9/site-packages/wandb/sdk/internal/internal_api.py", line 2384, in upload_urls
    query_result = self.gql(
  File "/home/uosai/Desktop/miniconda3/envs/marl/lib/python3.9/site-packages/wandb/sdk/internal/internal_api.py", line 341, in gql
    ret = self._retry_gql(
  File "/home/uosai/Desktop/miniconda3/envs/marl/lib/python3.9/site-packages/wandb/sdk/lib/retry.py", line 147, in __call__
    retry_timedelta_triggered = check_retry_fn(e)
  File "/home/uosai/Desktop/miniconda3/envs/marl/lib/python3.9/site-packages/wandb/util.py", line 907, in no_retry_auth
    raise CommError(
wandb.errors.CommError: It appears that you do not have permission to access the requested resource. Please reach out to the project owner to grant you access. If you have the correct permissions, verify that there are no issues with your networking setup.(Error 404: Not Found)
2024-05-31 21:18:31,391 ERROR   wandb-upload_4:1510841 [internal_api.py:execute():373] 404 response executing GraphQL.
2024-05-31 21:18:31,391 ERROR   wandb-upload_4:1510841 [internal_api.py:execute():374] {"errors":[{"message":"run StarCraft2_3m/cgmjqjo6 not found during createRunFiles","path":["createRunFiles"]}],"data":{"createRunFiles":null}}
2024-05-31 21:18:31,391 ERROR   Thread-11 :1510841 [step_upload.py:_handle_event():200] Failed to upload file: /home/uosai/Desktop/on-policy/onpolicy/scripts/results/StarCraft2/3m/rmappo/MAPPO/wandb/run-20240531_211812-cgmjqjo6/files/config.yaml
Traceback (most recent call last):
  File "/home/uosai/Desktop/miniconda3/envs/marl/lib/python3.9/site-packages/wandb/sdk/lib/retry.py", line 131, in __call__
    result = self._call_fn(*args, **kwargs)
  File "/home/uosai/Desktop/miniconda3/envs/marl/lib/python3.9/site-packages/wandb/sdk/internal/internal_api.py", line 369, in execute
    return self.client.execute(*args, **kwargs)  # type: ignore
  File "/home/uosai/Desktop/miniconda3/envs/marl/lib/python3.9/site-packages/wandb/vendor/gql-0.2.0/wandb_gql/client.py", line 52, in execute
    result = self._get_result(document, *args, **kwargs)
  File "/home/uosai/Desktop/miniconda3/envs/marl/lib/python3.9/site-packages/wandb/vendor/gql-0.2.0/wandb_gql/client.py", line 60, in _get_result
    return self.transport.execute(document, *args, **kwargs)
  File "/home/uosai/Desktop/miniconda3/envs/marl/lib/python3.9/site-packages/wandb/sdk/lib/gql_request.py", line 59, in execute
    request.raise_for_status()
  File "/home/uosai/Desktop/miniconda3/envs/marl/lib/python3.9/site-packages/requests/models.py", line 1021, in raise_for_status
    raise HTTPError(http_error_msg, response=self)
requests.exceptions.HTTPError: 404 Client Error: Not Found for url: https://api.wandb.ai/graphql

During handling of the above exception, another exception occurred:

Traceback (most recent call last):
  File "/home/uosai/Desktop/miniconda3/envs/marl/lib/python3.9/concurrent/futures/thread.py", line 58, in run
    result = self.fn(*self.args, **self.kwargs)
  File "/home/uosai/Desktop/miniconda3/envs/marl/lib/python3.9/site-packages/wandb/filesync/step_upload.py", line 288, in run_and_notify
    self._do_upload_sync(event)
  File "/home/uosai/Desktop/miniconda3/envs/marl/lib/python3.9/site-packages/wandb/filesync/step_upload.py", line 330, in _do_upload_sync
    job.run()
  File "/home/uosai/Desktop/miniconda3/envs/marl/lib/python3.9/site-packages/wandb/filesync/upload_job.py", line 57, in run
    self.push()
  File "/home/uosai/Desktop/miniconda3/envs/marl/lib/python3.9/site-packages/wandb/filesync/upload_job.py", line 106, in push
    _, upload_headers, result = self._api.upload_urls(project, [self.save_name])
  File "/home/uosai/Desktop/miniconda3/envs/marl/lib/python3.9/site-packages/wandb/apis/normalize.py", line 73, in wrapper
    raise err
  File "/home/uosai/Desktop/miniconda3/envs/marl/lib/python3.9/site-packages/wandb/apis/normalize.py", line 41, in wrapper
    return func(*args, **kwargs)
  File "/home/uosai/Desktop/miniconda3/envs/marl/lib/python3.9/site-packages/wandb/sdk/internal/internal_api.py", line 2384, in upload_urls
    query_result = self.gql(
  File "/home/uosai/Desktop/miniconda3/envs/marl/lib/python3.9/site-packages/wandb/sdk/internal/internal_api.py", line 341, in gql
    ret = self._retry_gql(
  File "/home/uosai/Desktop/miniconda3/envs/marl/lib/python3.9/site-packages/wandb/sdk/lib/retry.py", line 147, in __call__
    retry_timedelta_triggered = check_retry_fn(e)
  File "/home/uosai/Desktop/miniconda3/envs/marl/lib/python3.9/site-packages/wandb/util.py", line 907, in no_retry_auth
    raise CommError(
wandb.errors.CommError: It appears that you do not have permission to access the requested resource. Please reach out to the project owner to grant you access. If you have the correct permissions, verify that there are no issues with your networking setup.(Error 404: Not Found)
2024-05-31 21:18:31,394 ERROR   wandb-upload_5:1510841 [internal_api.py:execute():373] 404 response executing GraphQL.
2024-05-31 21:18:31,394 ERROR   wandb-upload_5:1510841 [internal_api.py:execute():374] {"errors":[{"message":"run StarCraft2_3m/cgmjqjo6 not found during createRunFiles","path":["createRunFiles"]}],"data":{"createRunFiles":null}}
2024-05-31 21:18:31,394 ERROR   Thread-11 :1510841 [step_upload.py:_handle_event():200] Failed to upload file: /home/uosai/Desktop/on-policy/onpolicy/scripts/results/StarCraft2/3m/rmappo/MAPPO/wandb/run-20240531_211812-cgmjqjo6/files/output.log
Traceback (most recent call last):
  File "/home/uosai/Desktop/miniconda3/envs/marl/lib/python3.9/site-packages/wandb/sdk/lib/retry.py", line 131, in __call__
    result = self._call_fn(*args, **kwargs)
  File "/home/uosai/Desktop/miniconda3/envs/marl/lib/python3.9/site-packages/wandb/sdk/internal/internal_api.py", line 369, in execute
    return self.client.execute(*args, **kwargs)  # type: ignore
  File "/home/uosai/Desktop/miniconda3/envs/marl/lib/python3.9/site-packages/wandb/vendor/gql-0.2.0/wandb_gql/client.py", line 52, in execute
    result = self._get_result(document, *args, **kwargs)
  File "/home/uosai/Desktop/miniconda3/envs/marl/lib/python3.9/site-packages/wandb/vendor/gql-0.2.0/wandb_gql/client.py", line 60, in _get_result
    return self.transport.execute(document, *args, **kwargs)
  File "/home/uosai/Desktop/miniconda3/envs/marl/lib/python3.9/site-packages/wandb/sdk/lib/gql_request.py", line 59, in execute
    request.raise_for_status()
  File "/home/uosai/Desktop/miniconda3/envs/marl/lib/python3.9/site-packages/requests/models.py", line 1021, in raise_for_status
    raise HTTPError(http_error_msg, response=self)
requests.exceptions.HTTPError: 404 Client Error: Not Found for url: https://api.wandb.ai/graphql

During handling of the above exception, another exception occurred:

Traceback (most recent call last):
  File "/home/uosai/Desktop/miniconda3/envs/marl/lib/python3.9/concurrent/futures/thread.py", line 58, in run
    result = self.fn(*self.args, **self.kwargs)
  File "/home/uosai/Desktop/miniconda3/envs/marl/lib/python3.9/site-packages/wandb/filesync/step_upload.py", line 288, in run_and_notify
    self._do_upload_sync(event)
  File "/home/uosai/Desktop/miniconda3/envs/marl/lib/python3.9/site-packages/wandb/filesync/step_upload.py", line 330, in _do_upload_sync
    job.run()
  File "/home/uosai/Desktop/miniconda3/envs/marl/lib/python3.9/site-packages/wandb/filesync/upload_job.py", line 57, in run
    self.push()
  File "/home/uosai/Desktop/miniconda3/envs/marl/lib/python3.9/site-packages/wandb/filesync/upload_job.py", line 106, in push
    _, upload_headers, result = self._api.upload_urls(project, [self.save_name])
  File "/home/uosai/Desktop/miniconda3/envs/marl/lib/python3.9/site-packages/wandb/apis/normalize.py", line 73, in wrapper
    raise err
  File "/home/uosai/Desktop/miniconda3/envs/marl/lib/python3.9/site-packages/wandb/apis/normalize.py", line 41, in wrapper
    return func(*args, **kwargs)
  File "/home/uosai/Desktop/miniconda3/envs/marl/lib/python3.9/site-packages/wandb/sdk/internal/internal_api.py", line 2384, in upload_urls
    query_result = self.gql(
  File "/home/uosai/Desktop/miniconda3/envs/marl/lib/python3.9/site-packages/wandb/sdk/internal/internal_api.py", line 341, in gql
    ret = self._retry_gql(
  File "/home/uosai/Desktop/miniconda3/envs/marl/lib/python3.9/site-packages/wandb/sdk/lib/retry.py", line 147, in __call__
    retry_timedelta_triggered = check_retry_fn(e)
  File "/home/uosai/Desktop/miniconda3/envs/marl/lib/python3.9/site-packages/wandb/util.py", line 907, in no_retry_auth
    raise CommError(
wandb.errors.CommError: It appears that you do not have permission to access the requested resource. Please reach out to the project owner to grant you access. If you have the correct permissions, verify that there are no issues with your networking setup.(Error 404: Not Found)
2024-05-31 21:18:31,395 INFO    MainThread:1510841 [internal.py:handle_exit():76] Internal process exited
